File: PPMS/acdH_1_9K.dat
[Header]
; ACMS II Data File (default extension .dat)
; Copyright (c) 2014, Quantum Design, Inc. All rights reserved.
TITLE,
FILEOPENTIME,3909685167.027,11/20/2023,10:38 pm
BYAPP,ACMS II,1.0,1.2
INFO,DYNACOOL ACMS II Option Release 1.0.8 Build 47,APPNAME
INFO,Quantum Design Linear Motor Servo Controller,MOTOR_MODULE_NAME
INFO,3101-100 N4,MOTOR_HW_VERSION
INFO,MMC1404,MOTOR_SERIAL_NUMBER
INFO,SRV No X-over 01.03.11,MOTOR_SOFTWARE_VERSION
INFO,ACMS,ACMS_MODULE_NAME
INFO,3101-430 D2,ACMS_HW_VERSION
INFO,ACMSII272,ACMS_SERIAL_NUMBER
INFO,00.14.14,ACMS_SOFTWARE_VERSION
INFO,WF261,COIL_SERIAL_NUMBER
INFO,0,MOMENT_UNITS
INFO,,SAMPLE_MATERIAL
INFO,,SAMPLE_COMMENT
INFO,,SAMPLE_MASS
INFO,,SAMPLE_VOLUME
INFO,,SAMPLE_MOLECULAR_WEIGHT
INFO,,SAMPLE_SIZE
INFO,,SAMPLE_SHAPE
DATATYPE,COMMENT,1
DATATYPE,TIME,2
STARTUPAXIS,X,2
STARTUPAXIS,Y1,5
STARTUPGROUP, AC
FIELDGROUP, AC, 2,3,4,5,6,7,8,9,10,11,12,13,14,15,16,20,21,22,23,24,25,35,43,44,45,46,47,48,49
FIELDGROUP, DC, 2,3,4,17,18,19,20,21,23,24,25,35,36,37,43,44,45,46,47,48,49,50,51
FIELDGROUP, Diagnostic, 26,27,28,29,30,31,32,33,34,38,39,40,41,42,52,53,54,55,56,57,58,59,60,61,62,63,64,65,66,67,68,69
[Data]
Comment,Time Stamp (sec),Temperature (K),Magnetic Field (Oe),AC Moment (emu),AC Std. Dev. (emu),AC Phase (deg),AC Phase Std. Dev. (deg),AC Suscept. (emu/Oe),AC Suscept. Std. Dev. (emu/Oe),AC X'  (emu/Oe),AC X" (emu/Oe),AC X' Std. Dev. (emu/Oe),AC X" Std. Dev. (emu/Oe),AC Drive (Oe),AC Frequency (Hz),DC Moment (emu),DC Std. Err. (emu),DC Quad. Moment (emu),Range (mV),"AC=1 DC=2 Locate=3",Measure Type,Measure Count,Measure Time (sec),Measure Number,AC X' Raw (emu/Oe),AC X" Raw (emu/Oe),DC M. Raw' (emu),DC M. Raw" (emu),Coil InPhase (V),Coil Quadrature (V),Null Status,Trim Ratio,Trim Phase (deg.),Max. Signal (mV),Motor Frequency (Hz),Motor Ampl. (mm),System Temp. (K),Min. Temperature (K),Max. Temperature (K),Min. Field (Oe),Max. Field (Oe),Pressure (Torr),Temp. Status (code),Field Status (code),Chamber Status (code),Measure Status (code),Center Position (mm),Transport Action,Motor Lag (deg),Motor Current (amps),Motor Heatsink Temp. (C),Motor Board Temp. (C),QMap 01,QMap 02,QMap 03,QMap 04,QMap 05,QMap 06,QMap 07,QMap 08,QMap 09,QMap 10,QMap 11,QMap 12,QMap 13,QMap 14,QMap 15,QMap 16
,3909685362.31192,1.89645504951477,-0.295025646686554,,,,,,,,,,,,,,,,,3,,,,,,,,,,,,,,,,,,,,,,0.0812407359480858,5,4,3,,37.6930004202127,2,,,30.3030319213867,35.190616607666,,,,,,,,,,,,,,,,
,3909686301.49159,1.90026669502258,-0.295025646686554,4.11035872727476E-5,6.06046838655719E-7,0.878423118386565,0.60710090594129,8.2252631813386E-6,1.21276391646396E-7,8.22429652178019E-6,1.26099659470841E-7,6.13787106593062E-10,6.14930433098902E-10,4.99723672866821,35.9447021484375,,,,1,1,3,647,18,6,8.21643249447798E-6,1.70103722801429E-7,,,5.11699838057211E-9,2.94425300917389E-7,5,0.610765099525452,226.086166381836,0.102742399132993,,,1.88545179367065,1.88818287849426,1.94672036170959,-0.295025646686554,-0.295025646686554,0.0802059844136238,5,4,3,0,37.6630006574392,1,,,29.3255138397217,34.7018585205078,,,,,,,,,,,,,,,,
sample offset = 18.63 mm touchdown = 16.1499995738268 mm,3909687550.00745,1.90109381228685,-0.193610578775406,2.44572059379193E-5,2.28424565547243E-7,0.321130594074265,0.382572889645459,8.18619376696656E-6,7.64571292179242E-8,8.18606518827907E-6,4.58816255996936E-8,1.0738346773009E-9,1.06819065997356E-9,2.98761630058289,100,,,,1,1,3,1800,18,1,8.17734062147555E-6,6.88075513572428E-8,,,4.10482048351923E-9,4.84489511620723E-7,5,0.837176144123077,198.943588256836,0.110157628911853,,,1.89627170562744,1.89551985263824,1.94652247428894,-0.202830135822296,-0.184391021728516,0.0798753499984741,5,4,3,0,37.6429995738268,1,,,29.3255138397217,35.190616607666,,,,,,,,,,,,,,,,
,3909688611.08388,1.90733707770705,-0.129073716700077,2.44148754635519E-5,4.34459421687397E-8,0.197101776891742,0.0775123371237212,8.17561089030775E-6,1.454838950396E-8,8.17556251479251E-6,2.8124658902423E-8,1.00715001303055E-9,8.76891835796406E-10,2.98630595207214,464.516143798828,,,,1,1,3,8384,18,7,8.16432488161957E-6,6.38961258593598E-8,,,2.07607656621533E-8,2.24094912937289E-6,5,0.916922092437744,186.859268188477,0.158075536149929,,,1.8945769071579,1.89742946624756,1.93616437911987,-0.184391021728516,-0.0737564116716385,0.0797090604901314,5,4,3,0,37.6829998784065,1,,,29.3255138397217,33.7243423461914,,,,,,,,,,,,,,,,
touchdown = 16.2499994039536 mm,3909689662.70053,1.89980766694703,-0.119854167103767,1.21572377357911E-5,1.02705535039531E-8,0.114069967572355,0.0352027609995972,8.18638247350636E-6,6.91593608887336E-9,8.18636624945683E-6,1.62982295438043E-8,1.62473685984218E-9,1.58770999944214E-9,1.48505616188049,1667.7060546875,,,,1,1,3,30208,18,3,8.15139623125501E-6,1.22999371705404E-7,,,6.95240778003647E-8,3.99271129936096E-6,5,0.978043019771576,179.621887207031,0.216286413869197,,,1.89851641654968,1.89570033550262,1.94466233253479,-0.147512823343277,-0.0921955108642578,0.0793172121047974,1,4,3,0,37.7429994039535,1,,,30.3030319213867,34.7018585205078,,,,,,,,,,,,,,,,
,3909690771.77498,1.89969386741882,-0.248927876353264,1.21882585744619E-5,3.43576252479367E-9,0.245089878487117,0.0120227079164638,8.16964078389539E-6,2.30294963590178E-9,8.16956603964487E-6,3.49465558836549E-8,2.53212552183613E-9,2.48511874608513E-9,1.49189651012421,7739.53466796875,,,,1,1,3,139776,18,9,7.98238981498969E-6,3.37539513593986E-7,,,8.41827386466321E-7,1.87581335922005E-5,5,0.713658332824707,163.009002685547,0.547776567611315,,,1.88604819774628,1.88595700263977,1.94226217269897,-0.313464730978012,-0.184391021728516,0.0790173858404159,5,4,3,0,37.7429994039535,1,,,28.8367557525635,35.190616607666,,,,,,,,,,,,,,,,
,3909692231.81337,1.85933041572571,199.806121826172,,,,,,,,,,,,,,,,,3,,,,,,,,,,,,,,,,,,,,,,0.0776053890585899,6,4,3,,37.7330007247925,2,,,30.3030319213867,34.7018585205078,,,,,,,,,,,,,,,,
,3909693172.70635,1.90022657195852,199.796905517578,4.02093091009284E-5,3.07364650890628E-7,0.612689339498563,0.345676430767709,8.04645836689451E-6,6.15080667175503E-8,8.04599831585393E-6,8.60427303290076E-8,9.51197716806896E-10,7.60944386194516E-10,4.99714374542236,100,,,,1,1,3,1800,18,10,8.03731866490422E-6,1.0856359034765E-7,,,1.07801341187042E-8,7.96240726685937E-7,5,0.836853623390198,198.946411132813,0.123314978546418,,,1.88535869121552,1.88529133796692,1.94892287254334,199.787689208984,199.806121826172,0.0788092911243439,5,4,3,0,37.7429994039535,1,,,29.3255138397217,35.190616607666,,,,,,,,,,,,,,,,
,3909694250.0143,1.90028660238525,199.778465270996,2.40304975538799E-5,5.7390142990693E-8,0.514786970898211,0.106010309372273,8.04541040456688E-6,1.92142194518295E-8,8.04508567254709E-6,7.22848482775257E-8,1.04562294741542E-9,8.78197660740289E-10,2.98685789108276,359.309020996094,,,,1,1,3,6528,18,6,8.03510847238856E-6,1.01669810709766E-7,,,2.40489406166944E-8,1.70759531670228E-6,5,0.900492131710052,187.997467041016,0.146256676777633,,,1.89362955093384,1.89427089691162,1.9458669424057,199.713928222656,199.843002319336,0.0791572704911232,5,4,3,0,37.6930004202127,1,,,29.8142719268799,34.7018585205078,,,,,,,,,,,,,,,,
touchdown = 16.270000487566 mm,3909695186.54987,1.89992517860312,199.60327911377,1.18739676579875E-5,1.37377277871583E-8,0.819778789935069,0.0475977497726266,7.97682920850127E-6,9.22888721170872E-9,7.97601273709575E-6,1.14127294217219E-7,1.64259472413855E-9,1.68043656930119E-9,1.4885573387146,1291.03442382812,,,,1,1,3,23552,18,2,7.94958639608444E-6,1.96616376952864E-7,,,8.15066663051311E-8,3.02229074122806E-6,5,0.973185896873474,181.416580200195,0.183921756275085,,,1.89747476577759,1.89545321464539,1.93879377841949,199.584838867187,199.621719360352,0.0790895819664001,1,4,3,0,37.763000487566,1,,,29.8142719268799,35.190616607666,,,,,,,,,,,,,,,,
,3909696298.3858,1.9009868367561,199.63094329834,1.17052491545323E-5,3.82631610965326E-9,0.821332345725717,0.0135335385238705,7.85314629724468E-6,2.56710641455901E-9,7.85233943602256E-6,1.1257063299489E-7,2.07718200463085E-9,2.21481098739243E-9,1.49051713943481,5990.39990234375,,,,1,1,3,108032,18,8,7.70201734463859E-6,3.76471001371502E-7,,,7.49923884768577E-7,1.38250263717055E-5,5,0.82927280664444,164.592926025391,0.465633482608403,,,1.88995039463043,1.89360845088959,1.95076382160187,199.603286743164,199.658599853516,0.0787975117564201,5,4,3,0,37.5830000482798,1,,,29.8142719268799,34.7018585205078,,,,,,,,,,,,,,,,
touchdown = 16.2499994039536 mm,3909697342.96436,1.90064507591236,399.566131591797,4.07121131560615E-5,1.23998760869716E-6,1.77651232702956,1.28226434021558,8.14690718438425E-6,2.48134109843873E-7,8.14299139643698E-6,2.52562444803171E-7,5.96126623876979E-10,5.79811773543644E-10,4.99724769592285,16.6785469055176,,,,1,1,3,300,18,3,8.14528098619143E-6,3.39032943619162E-7,,,3.55812446173331E-9,1.36395744476658E-7,5,0.309583753347397,235.079650878906,0.102153468529839,,,1.88588881492615,1.88999533653259,1.94006240367889,399.538482666016,399.593780517578,0.0784163028001785,5,4,3,0,37.7429994039535,1,,,29.8142719268799,35.6793746948242,,,,,,,,,,,,,,,,
,3909698398.66301,1.90116596595621,399.455490112305,3.97285991240813E-5,3.09113506345717E-7,1.09551124165752,0.321473470700262,7.95019390148907E-6,6.18575124016396E-8,7.94874070979657E-6,1.5200065689605E-7,6.69445717345168E-10,6.7199624326607E-10,4.99718618392944,77.4834442138672,,,,1,1,3,1400,18,9,7.93988401712352E-6,1.76733815453512E-7,,,1.33536488533537E-8,6.0906566545782E-7,5,0.81469589471817,203.983505249023,0.124118077351276,,,1.88457763195038,1.88557589054108,1.93932056427002,399.446258544922,399.464721679687,0.0784785896539688,5,4,3,0,37.653000115633,1,,,29.8142719268799,34.7018585205078,,,,,,,,,,,,,,,,
,3909699434.61449,1.89138281345367,399.556915283203,,,,,,,,,,,,,,,,,3,,,,,,,,,,,,,,,,,,,,,,0.0787694081664085,6,4,3,,37.7330007247925,2,,,29.8142719268799,35.190616607666,,,,,,,,,,,,,,,,
sample offset = 18.63 mm,3909700403.86866,1.89916360154748,399.60302734375,1.15373504919336E-5,6.60659616756935E-8,2.3295138980335,0.245286925564796,7.73977438396074E-6,4.43200228845234E-8,7.73337815758923E-6,3.14594638124546E-7,6.23508323303209E-9,6.1374055638577E-9,1.49065721035004,1001.06951904297,,,,1,1,3,18048,18,1,7.71198080796872E-6,3.77935174084312E-7,,,1.16504029534781E-7,2.27453568868441E-6,5,0.96217954158783,182.984954833984,0.167378032434907,,,1.89954268932343,1.89529585838318,1.94265675544739,399.575378417969,399.630676269531,0.0784191191196442,1,4,3,0,37.7429994039535,1,,,28.8367557525635,34.2131004333496,,,,,,,,,,,,,,,,
,3909701518.11631,1.90074848341154,399.4462890625,1.10021314633235E-5,4.11639226432626E-9,2.5094511571921,0.0159863661144337,7.34551726278153E-6,2.74828841473005E-9,7.33847300579156E-6,3.21617476344255E-7,1.73287686056978E-9,1.81238866162496E-9,1.49780213832855,4636.53271484375,,,,1,1,3,83968,18,7,7.22273701661713E-6,5.32954187292498E-7,,,7.88893146363989E-7,1.00071909230337E-5,5,0.898887693881988,168.629257202148,0.407636784709577,,,1.89377629756927,1.89321291446686,1.94335293769836,399.390960693359,399.501617431641,0.0784314200282097,5,4,3,0,37.6129998110533,1,,,29.8142719268799,33.7243423461914,,,,,,,,,,,,,,,,
,3909702565.7213,1.90010660830356,599.787139892578,4.07160058612136E-5,1.66639056476809E-6,3.34768234760261,1.72114086680607,8.14768459930361E-6,3.33461606898911E-7,8.13378110771623E-6,4.75782746101322E-7,6.07510141163326E-10,6.19846223708294E-10,4.99724864959717,12.9210376739502,,,,1,1,3,232,18,2,8.1429531003448E-6,5.84559112920367E-7,,,5.17060527727153E-9,1.0584720300244E-7,5,0.250318467617035,231.444107055664,0.0976026062856147,,,1.88852214813232,1.88907063007355,1.95650005340576,599.731811523437,599.842468261719,0.0782205164432526,5,4,3,0,37.7829997085333,1,,,28.8367557525635,34.7018585205078,,,,,,,,,,,,,,,,
,3909703620.82995,1.90022509785655,599.805572509766,3.92898524075797E-5,4.05812955572489E-7,1.31113153924078,0.448713046588682,7.86235463560247E-6,8.12078737108558E-8,7.86029613525062E-6,1.79902979807879E-7,7.16032236035311E-10,6.48508460646498E-10,4.99721193313599,60,,,,1,1,3,1080,18,8,7.85146451876616E-6,2.08400896026326E-7,,,1.20343415233037E-8,4.67240880652753E-7,5,0.775291323661804,210.43586730957,0.111549658319864,,,1.88555026054382,1.88654386997223,1.95380675792694,599.787109375,599.824035644531,0.0782766789197922,5,4,3,0,37.7529999457598,1,,,29.3255138397217,34.7018585205078,,,,,,,,,,,,,,,,
touchdown = 16.2400007247925 mm,3909704542.29853,1.89973881887418,599.888549804687,2.32142142727797E-5,1.30101798744055E-7,1.62659501467979,0.23639554143841,7.7704409746923E-6,4.35486782349289E-8,7.76730985182253E-6,2.20568825897297E-7,1.02775228810345E-9,1.00681395256113E-9,2.98750281333923,166.844924926758,,,,1,1,3,3008,18,3,7.75867202171964E-6,2.41147743325579E-7,,,2.43290827484088E-8,7.6654951897126E-7,5,0.861871004104614,192.616287231445,0.121789101274053,,,1.89681398868561,1.89412462711334,1.95768129825592,599.842468261719,599.934631347656,0.0783547684550285,5,4,3,0,37.7330007247925,1,,,29.8142719268799,34.7018585205078,,,,,,,,,,,,,,,,
,3909705607.26288,1.90035394604704,599.897766113281,2.23301512921032E-5,2.56646247356448E-8,3.73847118793928,0.051306666293792,7.48361105678339E-6,8.60110918763855E-9,7.46768640524157E-6,4.87948974976816E-7,9.59720067590276E-10,8.96718153495786E-10,2.98387384414673,773.5537109375,,,,1,1,3,13952,18,9,7.45007742740858E-6,5.36480621006449E-7,,,2.51934842765422E-7,3.40066708304221E-6,5,0.949445366859436,184.39094543457,0.199126978234255,,,1.89490413665771,1.8946418762207,1.95071315765381,599.879333496094,599.916198730469,0.0784845128655434,5,4,3,0,37.6330008946657,1,,,29.8142719268799,35.190616607666,,,,,,,,,,,,,,,,
,3909706685.56262,1.89199662208557,599.916198730469,,,,,,,,,,,,,,,,,3,,,,,,,,,,,,,,,,,,,,,,0.0785590931773186,6,4,3,,37.6630006574392,2,,,30.3030319213867,34.7018585205078,,,,,,,,,,,,,,,,
sample offset = 18.63 mm,3909707795.55469,1.90404686746718,799.565582275391,3.72753114043857E-5,8.49962926431691E-6,9.55870945367299,10.5757334368291,7.45916612546044E-6,1.7008616239194E-6,7.3556027938418E-6,1.23865524922924E-6,2.44172254259222E-9,2.42081946438072E-9,4.99724912643433,10,,,,1,1,3,180,18,1,7.36449784346581E-6,1.36404505577678E-6,,,1.15272822398538E-8,7.44668007257587E-8,5,0.217154681682587,226.436767578125,0.0995701815103452,,,1.88999462127686,1.89700257778168,1.96050548553467,799.537963867187,799.593200683594,0.0783378854393959,5,4,3,0,37.6630006574392,1,,,29.3255138397217,34.2131004333496,,,,,,,,,,,,,,,,
,3909708813.23392,1.88324904441834,799.574829101562,,,,,,,,,,,,,,,,,3,,,,,,,,,,,,,,,,,,,,,,0.0780799314379692,6,4,3,,37.7429994039535,2,,,29.8142719268799,35.6793746948242,,,,,,,,,,,,,,,,
,3909709771.29582,1.90001701822849,799.814514160156,2.27159106382145E-5,1.64714210369591E-7,2.14412491191442,0.312862911316576,7.6034647174341E-6,5.51331050272016E-8,7.59814135841413E-6,2.84470748622656E-7,1.02353317231923E-9,9.70422051073325E-10,2.98757362365723,129.281768798828,,,,1,1,3,2328,18,2,7.58952514375109E-6,3.04506485247674E-7,,,2.36309727341677E-8,5.80647750325625E-7,5,0.851013600826263,195.247207641602,0.110452105832168,,,1.89368760585785,1.89463770389557,1.95520758628845,799.814514160156,799.814514160156,0.0783334597945213,5,4,3,0,37.6829998784065,1,,,29.8142719268799,35.190616607666,,,,,,,,,,,,,,,,
,3909710832.85194,1.90005681039388,799.869812011719,2.15888246531684E-5,3.40735000273233E-8,4.75478366750167,0.0718654463081863,7.23149584299892E-6,1.14134223498753E-8,7.20660926693931E-6,5.9942889567908E-7,9.95570658100915E-10,9.13600213952289E-10,2.98538851737976,600,,,,1,1,3,10816,18,8,7.19194483551072E-6,6.37098954097064E-7,,,2.30295267300562E-7,2.54549763667455E-6,5,0.933221757411957,185.679626464844,0.178648103944616,,,1.89324748516083,1.89468848705292,1.94818222522736,799.832946777344,799.906677246094,0.0783237367868423,5,4,3,0,37.7330007247925,1,,,29.8142719268799,34.2131004333496,,,,,,,,,,,,,,,,
touchdown = 16.21999964118 mm,3909711786.93547,1.89982422476723,799.879058837891,9.79892879784749E-6,7.72801041429101E-9,7.01892366863855,0.0363461984103863,6.54608968140081E-6,5.16263055629723E-9,6.49703228024046E-6,7.99913536862334E-7,1.55708961142264E-9,1.53345266493742E-9,1.49691331386566,2151.72412109375,,,,1,1,3,38912,18,4,6.44650282853582E-6,9.01203174290087E-7,,,5.85156726629066E-7,4.10653024118801E-6,5,0.976194798946381,177.4853515625,0.25269331182299,,,1.89727532863617,1.89387762546539,1.94788873195648,799.869873046875,799.888244628906,0.0783236473798752,5,4,3,0,37.71299964118,1,,,29.3255138397217,33.7243423461914,,,,,,,,,,,,,,,,
,3909712893.29317,1.90220789296911,799.694702148438,8.727139899765E-6,3.97100014105022E-9,5.63013532460382,0.0212245574835787,5.85854605801843E-6,2.66574014968717E-9,5.8302840660449E-6,5.7476049198439E-7,3.83664469533823E-9,3.7586392925742E-9,1.48964262008667,9984,,,,1,1,3,179712,18,10,5.6585312325785E-6,7.82115723156084E-7,,,2.72397824119253E-6,1.73712533069192E-5,5,0.540993750095367,162.837036132813,0.629250366817508,,,1.88123381137848,1.88572669029236,1.95677983760834,799.685485839844,799.703918457031,0.077795997262001,5,4,3,0,37.7429994039535,1,,,29.3255138397217,34.7018585205078,,,,,,,,,,,,,,,,
touchdown = 16.2499994039536 mm,3909713919.87087,1.9005508170895,999.500762939453,3.7499329694404E-5,7.25793364275969E-7,2.50927119503018,0.83042321071634,7.50400447131503E-6,1.45238773470407E-7,7.49680925905901E-6,3.28533162409825E-7,5.8018103731365E-10,5.6150943456248E-10,4.99724245071411,27.8240184783936,,,,1,1,3,500,18,5,7.49013012567442E-6,3.79092265609504E-7,,,9.28499588326304E-9,2.08257752376539E-7,5,0.498580157756805,232.26318359375,0.101644846645297,,,1.88547313213348,1.88859975337982,1.95980381965637,999.454650878906,999.546875,0.0777855068445206,5,4,3,0,37.7429994039535,1,,,29.8142719268799,34.2131004333496,,,,,,,,,,,,,,,,
sample offset = 18.63 mm,3909714995.5095,1.89859054823342,999.362487792969,2.22350392517603E-5,2.22527328424176E-7,3.14674467733388,0.437485080398649,7.4424012372078E-6,7.4483235474636E-8,7.43117971779509E-6,4.0853907698421E-7,1.06849403450766E-9,1.01736766772058E-9,2.98761630058289,100,,,,1,1,3,1800,18,1,7.4222883011202E-6,4.29160906797108E-7,,,2.55121701542294E-8,4.39693934595198E-7,5,0.837177932262421,198.990310668945,0.113477090804027,,,1.89517664909363,1.89048993587494,1.95430183410645,999.362487792969,999.362487792969,0.0781368091702461,1,4,3,0,37.7330007247925,1,,,29.8142719268799,34.7018585205078,,,,,,,,,,,,,,,,
,3909716017.99905,1.89182806015015,999.657531738281,,,,,,,,,,,,,,,,,3,,,,,,,,,,,,,,,,,,,,,,0.0782525315880775,6,4,3,,37.6930004202127,2,,,28.8367557525635,35.6793746948242,,,,,,,,,,,,,,,,
,3909717003.15949,1.90013185803762,999.482330322266,9.28870122722389E-6,1.19301070375311E-8,8.94772390666021,0.0605191738009882,6.25478110906043E-6,8.03343829261266E-9,6.17866454302292E-6,9.72826391012596E-7,1.88114818818159E-9,1.85032365340749E-9,1.48505616188049,1667.7060546875,,,,1,1,3,30208,18,3,6.13982672859674E-6,1.04933626206536E-6,,,5.2203127154371E-7,3.00594609825566E-6,5,0.978305876255035,179.61994934082,0.207519309041631,,,1.89971590042114,1.89521014690399,1.94108319282532,999.473083496094,999.491577148438,0.0783436521887779,5,4,3,0,37.5729995064735,1,,,29.3255138397217,34.2131004333496,,,,,,,,,,,,,,,,
,3909718113.36262,1.90143113710531,999.445434570312,7.87073044498879E-6,3.416100908072E-9,7.16213046281988,0.0203225842237368,5.27565443821134E-6,2.28977069447505E-9,5.23449021261019E-6,6.57755247418939E-7,2.50297983732304E-9,2.48574317264029E-9,1.49189651012421,7739.53466796875,,,,1,1,3,139776,18,9,5.09183035124754E-6,8.36003974166126E-7,,,2.02420380901458E-6,1.19553587865084E-5,5,0.714707255363464,162.862274169922,0.5490213527498,,,1.88544273376465,1.88949763774872,1.9477002620697,999.436218261719,999.454650878906,0.0778193324804306,5,4,3,0,37.6330008946657,1,,,29.8142719268799,35.6793746948242,,,,,,,,,,,,,,,,
,3909719150.41989,1.90021827410138,1199.45440673828,3.71361126879295E-5,9.63764819531197E-7,3.54057680195482,1.13575286397355,7.43131672978065E-6,1.92859217310704E-7,7.41713267674109E-6,4.58923952237507E-7,6.02883747107054E-10,5.74807789995155E-10,4.99724531173706,21.5469608306885,,,,1,1,3,387,18,4,7.41230929443008E-6,5.22092946704478E-7,,,9.61252055731165E-9,1.60108605484766E-7,5,0.392872124910355,235.358810424805,0.103866732812298,,,1.88607788085938,1.88696825504303,1.9571750164032,1199.40832519531,1199.50048828125,0.0779706314206123,5,4,3,0,37.6230003528595,1,,,29.3255138397217,35.6793746948242,,,,,,,,,,,,,,,,
,3909720208.03515,1.90022557483444,1199.43597412109,3.56133844027272E-5,2.80032280564273E-7,3.62847302575436,0.36390551583582,7.12674804188911E-6,5.60384681390839E-8,7.11246177394234E-6,4.51026791642348E-7,8.51139158604693E-10,7.12233709642144E-10,4.99714374542236,100,,,,1,1,3,1800,18,10,7.10379485164377E-6,4.70747491419033E-7,,,4.67222456279615E-8,7.03764058584966E-7,5,0.837641894817352,199.012161254883,0.125403016849067,,,1.88785898685455,1.88708794116974,1.95769965648651,1199.38989257812,1199.48205566406,0.0777245163917542,5,4,3,0,37.7230001829863,1,,,29.3255138397217,34.2131004333496,,,,,,,,,,,,,,,,
touchdown = 16.2000004202127 mm,3909721127.11787,1.8999671054764,1199.38067626953,2.04272480206391E-5,7.07334590089712E-8,5.4219330336573,0.15759173315561,6.83829194379343E-6,2.3678962648761E-8,6.80769651377643E-6,6.46146179178051E-7,9.52209712844612E-10,8.90535996660357E-10,2.98718571662903,278.571441650391,,,,1,1,3,5056,18,5,6.79808421284192E-6,6.67049863317248E-7,,,1.11202767882901E-7,1.11919942469285E-6,5,0.885954976081848,189.202560424805,0.136994334851961,,,1.89428424835205,1.89525020122528,1.95825123786926,1199.35302734375,1199.40832519531,0.0778060555458069,5,4,3,0,37.6930004202127,1,,,29.8142719268799,34.7018585205078,,,,,,,,,,,,,,,,
,3909722220.79153,1.9000341322415,1199.61120605469,8.98331215635332E-6,1.48672316786251E-8,10.2951837143226,0.0805671565364887,6.03491173817369E-6,9.98767819818298E-9,5.93775004891926E-6,1.07855646310512E-6,1.86442158631549E-9,1.72927267145268E-9,1.4885573387146,1291.03442382812,,,,1,1,3,23552,18,2,5.90779192881667E-6,1.13689881145209E-6,,,4.37213330428676E-7,2.2450274741459E-6,5,0.97366064786911,181.452102661133,0.185099629100132,,,1.89892339706421,1.89484322071075,1.94474685192108,1199.55590820312,1199.66650390625,0.0779413059353828,5,4,3,0,37.5830000482798,1,,,29.3255138397217,34.7018585205078,,,,,,,,,,,,,,,,
,3909723286.31296,1.89010715484619,1199.53747558594,,,,,,,,,,,,,,,,,3,,,,,,,,,,,,,,,,,,,,,,0.0779322013258934,6,4,3,,37.7330007247925,2,,,30.3030319213867,33.7243423461914,,,,,,,,,,,,,,,,
,3909724373.4689,1.90011698422553,1399.58325195312,3.62160208090974E-5,1.17747443348967E-6,4.77643954071529,1.41685119680752,7.24719345783986E-6,2.3562458880122E-7,7.22202528817855E-6,6.03459818270032E-7,5.58126303395952E-10,5.58022860061942E-10,4.99724769592285,16.6785469055176,,,,1,1,3,300,18,3,7.22051557334889E-6,6.81440448633611E-7,,,9.54081613713242E-9,1.20931645142264E-7,5,0.309123367071152,234.874328613281,0.0993560249273801,,,1.88569068908691,1.88654291629791,1.95704555511475,1399.58325195312,1399.58325195312,0.0774879455566406,5,4,3,0,37.7429994039535,1,,,29.3255138397217,34.7018585205078,,,,,,,,,,,,,,,,
,3909725392.52234,1.88326561450958,1399.52783203125,,,,,,,,,,,,,,,,,3,,,,,,,,,,,,,,,,,,,,,,0.0775261372327805,6,4,3,,37.7429994039535,2,,,29.8142719268799,36.1681327819824,,,,,,,,,,,,,,,,
,3909726350.01496,1.90001481584033,1399.62933349609,1.97257582474034E-5,1.12838145442453E-7,5.74804539345244,0.266219123961765,6.60301889226792E-6,3.77715470695821E-8,6.56981848751179E-6,6.61319539099956E-7,1.20169282108186E-9,1.06862359045723E-9,2.98738479614258,215.172409057617,,,,1,1,3,3880,18,4,6.56100280980742E-6,6.79373801139302E-7,,,8.72423679965095E-8,8.35273965549277E-7,5,0.873013913631439,190.69059753418,0.123007128458406,,,1.89430129528046,1.89517104625702,1.95810389518738,1399.58325195312,1399.67541503906,0.077665701508522,5,4,3,0,37.6630006574392,1,,,29.8142719268799,34.2131004333496,,,,,,,,,,,,,,,,
sample offset = 18.63 mm,3909727434.28098,1.89919525273144,1399.80444335938,8.70630833711566E-6,6.82969983685165E-8,11.0358340000561,0.3757405374046,5.8405837885903E-6,4.58167027900928E-8,5.73257770089044E-6,1.11802141965059E-6,6.40394762398037E-9,6.38704451796302E-9,1.49065721035004,1001.06951904297,,,,1,1,3,18048,18,1,5.70938522959509E-6,1.16290742788571E-6,,,3.46847008003692E-7,1.6833369897995E-6,5,0.962267220020294,183.029418945313,0.16423258438513,,,1.89928615093231,1.89513111114502,1.95703053474426,1399.78601074219,1399.82287597656,0.077738031744957,1,4,3,0,37.7230001829863,1,,,29.8142719268799,35.6793746948242,,,,,,,,,,,,,,,,
touchdown = 16.1400008946657 mm,3909728384.65445,1.90024839459044,1399.75836181641,6.8426935069708E-6,5.129190313447E-9,13.3116004956296,0.037064615092505,4.59551926870001E-6,3.44473896050766E-9,4.47204812253288E-6,1.05810346315624E-6,1.71283829965931E-9,1.72701596947671E-9,1.48899245262146,3591.36694335937,,,,1,1,3,65024,18,6,4.39777397424019E-6,1.15690047302507E-6,,,1.24175454629949E-6,4.66940269916449E-6,5,0.947769224643707,171.994232177734,0.33217277785032,,,1.89443612098694,1.89418947696686,1.95584404468536,1399.73071289062,1399.78601074219,0.0777489244937897,5,4,3,0,37.6330008946657,1,,,30.3030319213867,34.7018585205078,,,,,,,,,,,,,,,,
,3909729597.93467,1.90026895067293,1599.49072265625,3.56545338287238E-5,1.6398709754478E-6,4.79774554386958,2.0461074299869,7.1348328507924E-6,3.28154768840648E-7,7.10983347389503E-6,5.96747670484029E-7,6.21478246265042E-10,5.86183075320635E-10,4.99724864959717,12.9210376739502,,,,1,1,3,232,18,2,7.1161976560877E-6,6.93475315374337E-7,,,6.89862389435802E-9,9.25654344285931E-8,5,0.249987155199051,231.662887573242,0.100185893305108,,,1.88634300231934,1.88733005523682,1.95636880397797,1599.4814453125,1599.5,0.0775144398212433,5,4,3,0,37.6330008946657,1,,,29.8142719268799,34.7018585205078,,,,,,,,,,,,,,,,
touchdown = 16.2499994039536 mm,3909730499.59001,1.90074550728255,1599.56451416016,3.36528943527382E-5,5.44792363133087E-7,5.11773070231041,0.740310144084517,6.73431281970666E-6,1.09018919938068E-7,6.70746653933816E-6,6.00717718503859E-7,7.43693277424109E-10,6.7764733089762E-10,4.99722766876221,46.4285697937012,,,,1,1,3,835,18,7,6.69832486323045E-6,6.29981037305242E-7,,,2.86504491242567E-8,3.09254687635985E-7,5,0.706806063652039,218.273483276367,0.105807538464158,,,1.88691079616547,1.8904013633728,1.95912539958954,1599.55529785156,1599.57373046875,0.0773050040006638,5,4,3,0,37.7429994039535,1,,,29.3255138397217,35.190616607666,,,,,,,,,,,,,,,,
,3909731573.85857,1.90001401690655,1599.61981201172,1.90194385894007E-5,1.23768088747431E-7,6.1729666865757,0.296240778775563,6.36633328158844E-6,4.14286099396477E-8,6.32942006910745E-6,6.84573619883556E-7,9.88622148218354E-10,9.46555266121762E-10,2.98750281333923,166.844924926758,,,,1,1,3,3008,18,3,6.32105324517106E-6,7.00961468878733E-7,,,6.96688147172608E-8,6.24481714339709E-7,5,0.862016022205353,192.615234375,0.115538359533805,,,1.8940749168396,1.8958078622818,1.95402359962463,1599.59216308594,1599.6474609375,0.0776182189583778,5,4,3,0,37.6930004202127,1,,,30.7917900085449,34.2131004333496,,,,,,,,,,,,,,,,
,3909732597.10534,1.89119112491608,1599.53686523438,,,,,,,,,,,,,,,,,3,,,,,,,,,,,,,,,,,,,,,,0.0777538418769836,6,4,3,,37.6930004202127,2,,,29.8142719268799,35.6793746948242,,,,,,,,,,,,,,,,
,3909733598.59737,1.90032144231969,1599.67517089844,6.53621908910549E-6,6.49106358164736E-9,16.0179638850012,0.0504699778616779,4.39485636549954E-6,4.36449447482784E-9,4.2242270709189E-6,1.21271106479978E-6,1.69415831121535E-9,1.68526890836862E-9,1.48724293708801,2783.64306640625,,,,1,1,3,50176,18,5,4.16633000131273E-6,1.28852015017571E-6,,,1.06703039648437E-6,3.41589822028254E-6,5,0.9808349609375,175.033950805664,0.275086222191619,,,1.89793467521667,1.89580702781677,1.94585037231445,1599.6474609375,1599.70288085938,0.0775394737720489,5,4,3,0,37.7230001829863,1,,,29.3255138397217,35.190616607666,,,,,,,,,,,,,,,,
,3909734785.37967,1.89678919315338,1799.60107421875,,,,,,,,,,,,,,,,,3,,,,,,,,,,,,,,,,,,,,,,0.0777331069111824,5,4,3,,37.653000115633,2,,,28.3479976654053,34.7018585205078,,,,,,,,,,,,,,,,
,3909735723.42476,1.90022660994003,1799.63800048828,3.24394454077371E-5,7.72745363028343E-7,4.98870583875033,0.988408322016562,6.49147662379852E-6,1.54634532039526E-7,6.46688599442308E-6,5.64494723143936E-7,7.31099961327671E-10,8.32617673777704E-10,4.99723672866821,35.9447021484375,,,,1,1,3,647,18,6,6.45845616718823E-6,5.99537935747882E-7,,,2.07267838447933E-8,2.3152086825462E-7,5,0.610516846179962,226.21028137207,0.103143954344791,,,1.88809835910797,1.88465237617493,1.95958757400513,1799.61950683594,1799.65649414062,0.0773004740476608,5,4,3,0,37.6930004202127,1,,,29.3255138397217,35.6793746948242,,,,,,,,,,,,,,,,
,3909736799.55537,1.90006285755889,1799.70251464844,1.83864832456105E-5,1.54922621039182E-7,6.36009706771384,0.385094790082754,6.15431971283198E-6,5.1855666354938E-8,6.11644177854942E-6,6.81755892799987E-7,9.60089345786268E-10,9.15428635266014E-10,2.98757362365723,129.281768798828,,,,1,1,3,2328,18,2,6.10833017179182E-6,6.97585442177778E-7,,,5.36139133089364E-8,4.67295947714774E-7,5,0.851042449474335,195.327621459961,0.113731401746298,,,1.89740967750549,1.89468669891357,1.95781683921814,1799.6748046875,1799.73022460938,0.077583335340023,5,4,3,0,37.6829998784065,1,,,29.8142719268799,35.190616607666,,,,,,,,,,,,,,,,
touchdown = 16.2000004202127 mm,3909737706.23224,1.89988248667613,1799.82232666016,1.66928397742963E-5,4.3185796554234E-8,9.80591928068627,0.124194606686425,5.58979556756849E-6,1.44612766566226E-8,5.50813038001872E-6,9.52005359188245E-7,9.6674080637788E-10,9.09390360487736E-10,2.98630595207214,464.516143798828,,,,1,1,3,8384,18,7,5.49644124046259E-6,9.7497391277561E-7,,,2.70343352148927E-7,1.50801514564591E-6,5,0.916540324687958,186.897750854492,0.160203728811883,,,1.89618945121765,1.89278757572174,1.94534754753113,1799.76696777344,1799.87768554687,0.0776870772242546,5,4,3,0,37.6930004202127,1,,,29.3255138397217,35.190616607666,,,,,,,,,,,,,,,,
,3909738815.50485,1.90025632716938,1799.73022460938,6.43836459974835E-6,8.73532992161648E-9,17.9776397341142,0.0700170084034456,4.30109381759841E-6,5.83556164588995E-9,4.0911016901454E-6,1.32751459075701E-6,1.75285310891146E-9,1.74045934317E-9,1.49691331386566,2151.72412109375,,,,1,1,3,38912,18,4,4.04598388167534E-6,1.38657170610542E-6,,,8.89353316324559E-7,2.57612873610924E-6,5,0.976791381835938,177.635650634766,0.251649298481035,,,1.89821660518646,1.89482736587524,1.95306730270386,1799.71179199219,1799.74865722656,0.0777037292718887,5,4,3,0,37.71299964118,1,,,29.3255138397217,36.1681327819824,,,,,,,,,,,,,,,,
,3909739875.67933,1.88311815261841,1799.73022460938,,,,,,,,,,,,,,,,,3,,,,,,,,,,,,,,,,,,,,,,0.0773577317595482,6,4,3,,37.6930004202127,2,,,29.8142719268799,35.190616607666,,,,,,,,,,,,,,,,
,3909740947.34654,1.90021474338785,1999.61926269531,3.1380011144403E-5,7.34874466506598E-7,6.3023109654858,1.04260976134488,6.27946541595531E-6,1.47055996132744E-7,6.24151564648086E-6,6.89324557021911E-7,5.74595051508313E-10,5.81498256693184E-10,4.99724245071411,27.8240184783936,,,,1,1,3,500,18,5,6.23333908388621E-6,7.31838449188173E-7,,,1.92386409025858E-8,1.73379863355194E-7,5,0.49709752202034,232.346862792969,0.102662090414381,,,1.88601589202881,1.88887691497803,1.9528523683548,1999.61010742187,1999.62841796875,0.0772463604807854,5,4,3,0,37.71299964118,1,,,28.8367557525635,34.2131004333496,,,,,,,,,,,,,,,,
,3909741983.56998,1.88900685310364,1999.46252441406,,,,,,,,,,,,,,,,,3,,,,,,,,,,,,,,,,,,,,,,0.0773616507649422,6,4,3,,37.7330007247925,2,,,29.8142719268799,32.7468223571777,,,,,,,,,,,,,,,,
,3909742925.83065,1.90009731350478,1999.55474853516,1.60678931211117E-5,5.18565292318746E-8,9.76326110336799,0.15517675266046,5.37953049895083E-6,1.73615656060142E-8,5.30161788043091E-6,9.12247904375446E-7,9.02294642798493E-10,8.41671324310122E-10,2.98685789108276,359.309020996094,,,,1,1,3,6528,18,6,5.2918527297925E-6,9.30715081938898E-7,,,1.99549999635451E-7,1.12440156385674E-6,5,0.899991273880005,188.036315917969,0.147260547379021,,,1.89631009101868,1.89585793018341,1.95614647865295,1999.51794433594,1999.59155273438,0.077468603849411,5,4,3,0,37.653000115633,1,,,29.8142719268799,35.190616607666,,,,,,,,,,,,,,,,
,3909744029.47066,1.90017979572068,1999.46252441406,6.31317720008351E-6,1.06766589434684E-8,18.8890631702346,0.0875310867361695,4.25113700217861E-6,7.18939742315792E-9,4.02220125300322E-6,1.37624957461628E-6,1.66409339685715E-9,1.67568510583652E-9,1.48505616188049,1667.7060546875,,,,1,1,3,30208,18,3,3.98728527331826E-6,1.42297226823468E-6,,,7.02457469969886E-7,1.95117378609666E-6,5,0.9783735871315,179.710067749023,0.209513665457971,,,1.89804947376251,1.89620423316956,1.95170593261719,1999.44409179687,1999.48095703125,0.0776176825165749,5,4,3,0,37.6630006574392,1,,,28.8367557525635,34.7018585205078,,,,,,,,,,,,,,,,
touchdown = 16.21999964118 mm,3909744975.21229,1.90098897902457,1999.48101806641,4.43849582720002E-6,3.59386040031407E-9,15.9417825329011,0.0416303405156433,2.97782273666645E-6,2.4111499997087E-9,2.86329945921484E-6,8.17890248057566E-7,2.03601664488552E-9,1.99753086251433E-9,1.49051713943481,5990.39990234375,,,,1,1,3,108032,18,8,2.78312474463452E-6,8.98793037617796E-7,,,1.6456043567814E-6,4.98599047205062E-6,5,0.832858324050903,164.592529296875,0.479808110868268,,,1.89098298549652,1.89262080192566,1.94132530689239,1999.42578125,1999.53625488281,0.0774290934205055,5,4,3,0,37.71299964118,1,,,29.3255138397217,35.6793746948242,,,,,,,,,,,,,,,,
,3909746237.95227,1.90013854111297,2499.56787109375,2.88241748660413E-5,9.09697513087779E-7,7.6386045179347,1.43594199325944,5.76801278863412E-6,1.82039795194998E-7,5.71682862034745E-6,7.66708585724076E-7,5.5611492106663E-10,5.55409008114174E-10,4.99724531173706,21.5469608306885,,,,1,1,3,387,18,4,5.70992903728622E-6,8.16394014374736E-7,,,1.63166689048921E-8,1.23375592409047E-7,5,0.390464544296265,235.346878051758,0.0992489466358975,,,1.88520300388336,1.88687002658844,1.95582282543182,2499.56787109375,2499.56787109375,0.0773544684052467,5,4,3,0,37.7230001829863,1,,,28.3479976654053,34.7018585205078,,,,,,,,,,,,,,,,
touchdown = 16.2300001829863 mm,3909747139.70222,1.90090424546572,2499.48498535156,2.62312404485273E-5,2.86154522722845E-7,7.8138309088767,0.504689469118075,5.24920214757755E-6,5.72631301277297E-8,5.20046357103043E-6,7.13653860438093E-7,6.30345167829657E-10,6.11464119685893E-10,4.99718618392944,77.4834442138672,,,,1,1,3,1400,18,9,5.19284486367126E-6,7.29649505505471E-7,,,5.58287469587526E-8,3.98392238309953E-7,5,0.813083648681641,204.097518920898,0.116087135777653,,,1.88657772541046,1.88746726512909,1.95776402950287,2499.42041015625,2499.54956054687,0.0772014036774635,5,4,3,0,37.7230001829863,1,,,29.3255138397217,35.6793746948242,,,,,,,,,,,,,,,,
,3909748213.30964,1.89998831375976,2499.66015625,1.40869161411662E-5,7.29959392180572E-8,10.5053567420484,0.256059392151145,4.71578183530649E-6,2.44363578774846E-8,4.63673526619214E-6,8.59816485918188E-7,1.01288731976893E-9,8.85781307176298E-10,2.98718571662903,278.571441650391,,,,1,1,3,5056,18,5,4.62884660276864E-6,8.73701520761433E-7,,,1.44858692152638E-7,7.62037430490636E-7,5,0.88484799861908,189.25260925293,0.138801292639468,,,1.89597737789154,1.89423847198486,1.95519256591797,2499.66015625,2499.66015625,0.0774658173322678,5,4,3,0,37.6230003528595,1,,,29.3255138397217,31.7693061828613,,,,,,,,,,,,,,,,
,3909749260.20021,1.89452290534973,2499.71533203125,,,,,,,,,,,,,,,,,3,,,,,,,,,,,,,,,,,,,,,,0.0775652304291725,5,4,3,,37.6930004202127,2,,,29.3255138397217,34.2131004333496,,,,,,,,,,,,,,,,
,3909750256.20199,1.90075835960354,2499.61389160156,3.64592211953058E-6,4.01973678377951E-9,21.8679951732243,0.0601380011029986,2.4341814090339E-6,2.68375687343141E-9,2.25902856211921E-6,9.06658197787827E-7,1.83172981543383E-9,1.62609853758247E-9,1.49780213832855,4636.53271484375,,,,1,1,3,83968,18,7,2.20035320536124E-6,9.59618590592021E-7,,,1.3413206261248E-6,3.0451888051175E-6,5,0.903308153152466,168.830596923828,0.411960117203139,,,1.89518523216248,1.89284574985504,1.95777893066406,2499.58618164062,2499.6416015625,0.0772286280989647,5,4,3,0,37.6429995738268,1,,,29.8142719268799,34.2131004333496,,,,,,,,,,,,,,,,
,3909751425.59421,1.88465750217438,2999.50732421875,,,,,,,,,,,,,,,,,3,,,,,,,,,,,,,,,,,,,,,,0.0766806527972221,6,4,3,,37.6330008946657,2,,,30.3030319213867,37.1456527709961,,,,,,,,,,,,,,,,
,3909752364.42885,1.90030341798609,2999.47045898438,2.31059344721153E-5,3.70013012116804E-7,9.08257861841092,0.746401834224119,4.62376516771327E-6,7.40438902867591E-8,4.56579170981269E-6,7.29897519357517E-7,6.24809023754756E-10,6.20845020906609E-10,4.99721193313599,60,,,,1,1,3,1080,18,8,4.55849798727193E-6,7.46410279494964E-7,,,4.42146941281862E-8,2.71285197861459E-7,5,0.772229194641113,210.763244628906,0.117131160738346,,,1.88740956783295,1.88563358783722,1.95957088470459,2999.4521484375,2999.48876953125,0.0767044052481651,5,4,3,0,37.7429994039535,1,,,29.8142719268799,34.2131004333496,,,,,,,,,,,,,,,,
,3909753441.47098,1.90003446063156,2999.76550292969,1.23855247049549E-5,9.10379231083646E-8,11.0546248480536,0.360529217160024,4.14594220367847E-6,3.04741201153317E-8,4.06901351315494E-6,7.94962757621281E-7,9.58184225626345E-10,8.74935345856921E-10,2.98738479614258,215.172409057617,,,,1,1,3,3880,18,4,4.06245464021338E-6,8.05882758227214E-7,,,1.03135860740622E-7,5.17175578806928E-7,5,0.87178635597229,190.763092041016,0.124827471032348,,,1.89491534233093,1.89443218708038,1.95499670505524,2999.7470703125,2999.78393554687,0.0768834501504898,5,4,3,0,37.593000590086,1,,,29.8142719268799,34.7018585205078,,,,,,,,,,,,,,,,
touchdown = 16.1199998110533 mm,3909754352.35089,1.90013239221307,2999.71020507812,1.06094680304764E-5,2.75299295497119E-8,17.9178401568859,0.13415216485204,3.55560207456099E-6,9.22623776595501E-9,3.38315059622091E-6,1.09389129071977E-6,1.01443107423205E-9,9.78061572445856E-10,2.98387384414673,773.5537109375,,,,1,1,3,13952,18,9,3.36934979837961E-6,1.11432731419032E-6,,,5.12010487341286E-7,1.53738449171215E-6,5,0.948286890983582,184.538925170898,0.19970254728845,,,1.89507496356964,1.89365243911743,1.94520235061646,2999.65502929687,2999.76538085937,0.0769132077693939,5,4,3,0,37.6129998110533,1,,,29.3255138397217,34.7018585205078,,,,,,,,,,,,,,,,
,3909755476.70683,1.90053059705874,2999.9130859375,3.1647814860597E-6,5.23830269546323E-9,26.8367705578008,0.0911998430808787,2.12545166396775E-6,3.5180182990457E-9,1.8965326049949E-6,9.59535749232168E-7,1.77357689211706E-9,1.73981643911326E-9,1.48899245262146,3591.36694335937,,,,1,1,3,65024,18,6,1.85279195698398E-6,9.95841243429875E-7,,,1.06761058304983E-6,1.96352516468323E-6,5,0.950627207756042,172.186187744141,0.335733154279592,,,1.89661538600922,1.8947616815567,1.9437313079834,2999.9130859375,2999.9130859375,0.0767830237746239,5,4,3,0,37.7429994039535,1,,,29.3255138397217,34.7018585205078,,,,,,,,,,,,,,,,
sample offset = 18.63 mm touchdown = 16.2000004202127 mm,3909756530.0848,1.90338224813908,3499.63110351562,2.63986194845343E-5,8.56061059670267E-6,16.2293929027156,16.3437301135701,5.28263026649833E-6,1.71306460416771E-6,5.07211975396134E-6,1.47640906729787E-6,2.49163246726424E-9,2.41616307956777E-9,4.99724912643433,10,,,,1,1,3,180,18,1,5.06989880855619E-6,1.56911044139222E-6,,,1.44891707520856E-8,5.14848181865091E-8,5,0.215551033616066,226.276916503906,0.101872388014697,,,1.89038324356079,1.89497458934784,1.96169257164001,3499.61279296875,3499.6494140625,0.0765652731060982,5,4,3,0,37.6930004202127,1,,,28.8367557525635,34.7018585205078,,,,,,,,,,,,,,,,
,3909757585.25193,1.9002280027806,3499.51110839844,2.08345025436033E-5,5.19699966438358E-7,9.83802751551366,1.19390038414718,4.16921219616234E-6,1.03997656478014E-7,4.10790273215997E-6,7.1236611355498E-7,6.97733541392633E-10,6.59248359993316E-10,4.99722766876221,46.4285697937012,,,,1,1,3,835,18,7,4.10088151663013E-6,7.30549780598007E-7,,,3.3490351825094E-8,1.89367529657147E-7,5,0.702910661697388,218.544845581055,0.107601123083968,,,1.88682866096497,1.8869161605835,1.95831632614136,3499.46508789063,3499.55712890625,0.0764648765325546,5,4,3,0,37.6429995738268,1,,,29.8142719268799,34.7018585205078,,,,,,,,,,,,,,,,
,3909758623.36168,1.89118957519531,3499.5205078125,,,,,,,,,,,,,,,,,3,,,,,,,,,,,,,,,,,,,,,,0.0767425745725632,6,4,3,,37.7230001829863,2,,,29.8142719268799,34.2131004333496,,,,,,,,,,,,,,,,
,3909759568.53406,1.90021775235137,3499.60339355469,9.42723804821425E-6,3.45815151651983E-8,16.9866670371324,0.191071648922067,3.15779269375914E-6,1.15835895274194E-8,3.02002693350488E-6,9.2254648536739E-7,1.0189854628536E-9,9.18119949677994E-10,2.98538851737976,600,,,,1,1,3,10816,18,8,3.01023185992158E-6,9.37397074489901E-7,,,3.33832304022508E-7,1.06517829578934E-6,5,0.93147873878479,185.845718383789,0.184805152179817,,,1.89600384235382,1.89520025253296,1.95911145210266,3499.57568359375,3499.63110351562,0.0766187161207199,5,4,3,0,37.6930004202127,1,,,29.8142719268799,34.7018585205078,,,,,,,,,,,,,,,,
,3909760686.27305,1.90036160801396,3499.52978515625,2.92308101777432E-6,6.48339637607444E-9,30.0403505002009,0.123039138383762,1.96543614017602E-6,4.35933915999546E-9,1.70142512656877E-6,9.83916541069653E-7,1.66212557740738E-9,1.71312302586277E-9,1.48724293708801,2783.64306640625,,,,1,1,3,50176,18,5,1.66831491390199E-6,1.0105493491498E-6,,,8.33276580181064E-7,1.36649464366201E-6,5,0.98294997215271,175.366958618164,0.276692419801334,,,1.89788496494293,1.8955489397049,1.95451092720032,3499.5205078125,3499.5390625,0.0769642665982246,5,4,3,0,37.6630006574392,1,,,30.7917900085449,34.7018585205078,,,,,,,,,,,,,,,,
touchdown = 16.1700006574392 mm,3909761626.43507,1.90270206114141,3499.57568359375,1.85624582102376E-6,3.720818288114E-9,20.7837521954351,0.110233146830809,1.2461014447316E-6,2.4977925832288E-9,1.16501306201679E-6,4.42168944966107E-7,3.8466481125416E-9,3.24924664857782E-9,1.48964262008667,9984,,,,1,1,3,179712,18,10,1.11939940836523E-6,4.74201286039345E-7,,,1.515398707852E-6,3.42143357556779E-6,5,0.547060549259186,163.129196166992,0.652433002823298,,,1.88379538059235,1.88504481315613,1.9555379152298,3499.55712890625,3499.59423828125,0.076267421245575,5,4,3,0,37.6630006574392,1,,,29.8142719268799,34.7018585205078,,,,,,,,,,,,,,,,
,3909762808.13712,1.90024029303201,3999.58898925781,1.85777744637833E-5,6.06830602750239E-7,10.6116884440606,1.55457930570238,3.71760944547735E-6,1.21433231143317E-7,3.65403015370906E-6,6.84604721636771E-7,6.19595299695249E-10,6.11133005836536E-10,4.99723672866821,35.9447021484375,,,,1,1,3,647,18,6,3.6474083487919E-6,7.04900857448766E-7,,,2.48827234372584E-8,1.3079572269703E-7,5,0.60361248254776,226.590087890625,0.107159413512864,,,1.88663280010223,1.88723242282867,1.95770585536957,3999.57055664063,3999.607421875,0.0764235332608223,5,4,3,0,37.71299964118,1,,,29.8142719268799,33.7243423461914,,,,,,,,,,,,,,,,
sample offset = 18.63 mm touchdown = 16.1499995738268 mm,3909763729.39892,1.89868258424103,3999.64416503906,1.00588017096167E-5,2.10964379160402E-7,11.2502904299708,1.01331429252216,3.36683184773569E-6,7.06129428733009E-8,3.30213578833308E-6,6.56853047749055E-7,1.00716647441329E-9,9.70889800388516E-10,2.98761630058289,100,,,,1,1,3,1800,18,1,3.29689201077306E-6,6.65907798175823E-7,,,3.95071095837807E-8,1.95322225948757E-7,5,0.834847569465637,199.277526855469,0.109836394037405,,,1.895676612854,1.89212024211884,1.94264805316925,3999.57055664063,3999.7177734375,0.076515905559063,5,4,3,0,37.6429995738268,1,,,29.3255138397217,34.7018585205078,,,,,,,,,,,,,,,,
,3909764789.76575,1.89999081115485,3999.5888671875,8.33633968620536E-6,4.31681571383885E-8,15.9347888967498,0.275913083587529,2.79152230883139E-6,1.44553698888203E-8,2.68425747650565E-6,7.66393241441281E-7,1.04753264222155E-9,8.1444178362809E-10,2.98630595207214,464.516143798828,,,,1,1,3,8384,18,7,2.67719087430289E-6,7.77276872916906E-7,,,2.14669853448868E-7,7.34483137421193E-7,5,0.91433721780777,187.014205932617,0.162372087451882,,,1.89574229717255,1.89461278915405,1.95618605613709,3999.5888671875,3999.5888671875,0.0765774995088577,5,4,3,0,37.6930004202127,1,,,29.3255138397217,35.190616607666,,,,,,,,,,,,,,,,
,3909765852.6305,1.89573788642883,3999.64404296875,,,,,,,,,,,,,,,,,3,,,,,,,,,,,,,,,,,,,,,,0.0768866017460823,6,4,3,,37.7330007247925,2,,,29.8142719268799,34.7018585205078,,,,,,,,,,,,,,,,
,3909766841.92506,1.90154861711216,3999.42309570313,1.5936015075716E-6,3.1623352100787E-9,25.8764515136558,0.108837024100601,1.06817161697022E-6,2.1196746480863E-9,9.61073769580675E-7,4.66184311967667E-7,2.30663642304077E-9,2.31368514046484E-9,1.49189651012421,7739.53466796875,,,,1,1,3,139776,18,9,9.23157329270521E-7,4.90425939110247E-7,,,1.16348030587687E-6,2.16318221646361E-6,5,0.724269509315491,163.062194824219,0.566368175394836,,,1.88790333271027,1.88787877559662,1.96165001392365,3999.40454101562,3999.44165039063,0.0765071138739586,5,4,3,0,37.6429995738268,1,,,29.8142719268799,34.7018585205078,,,,,,,,,,,,,,,,
,3909767991.507,1.88451397418976,4499.841796875,,,,,,,,,,,,,,,,,3,,,,,,,,,,,,,,,,,,,,,,0.0764646977186203,6,4,3,,37.6930004202127,2,,,30.7917900085449,34.2131004333496,,,,,,,,,,,,,,,,
,3909768932.66417,1.9003026891582,4499.85083007812,1.45339409775909E-5,2.46822199462969E-7,12.1634125497756,0.852073605949245,2.90844965004354E-6,4.9392655492264E-8,2.84315681966094E-6,6.12812096530315E-7,7.35929699248917E-10,6.44696334909639E-10,4.99714374542236,100,,,,1,1,3,1800,18,10,2.83850982764063E-6,6.2062281792719E-7,,,6.15595254771506E-8,2.81232480858762E-7,5,0.834402084350586,199.333450317383,0.119620754252793,,,1.88637685775757,1.88493680953979,1.95039093494415,4499.8046875,4499.89697265625,0.0764723271131516,5,4,3,0,37.7330007247925,1,,,28.8367557525635,34.7018585205078,,,,,,,,,,,,,,,,
,3909770006.873,1.90014495489038,4499.9248046875,7.45687826362921E-6,5.51134218575013E-8,15.005443039516,0.379027952111747,2.49656278790218E-6,1.84519732331564E-8,2.41143307856716E-6,6.46387083356415E-7,9.77822845483369E-10,8.74011484830671E-10,2.98685789108276,359.309020996094,,,,1,1,3,6528,18,6,2.4061061195861E-6,6.54620264496256E-7,,,1.39913335361896E-7,5.11207488784748E-7,5,0.897537767887116,188.165069580078,0.14632360070981,,,1.89692950248718,1.89438986778259,1.96144413948059,4499.841796875,4500.0078125,0.0767436251044273,5,4,3,0,37.71299964118,1,,,29.3255138397217,33.7243423461914,,,,,,,,,,,,,,,,
touchdown = 16.1700006574392 mm,3909770943.5313,1.89952590625886,4499.92456054687,2.93441734429237E-6,1.48602911355547E-8,26.0636208613611,0.277205043539022,1.97131629932798E-6,9.98301560112348E-9,1.77084669436908E-6,8.66135057042653E-7,1.82930731112735E-9,1.76537855192233E-9,1.4885573387146,1291.03442382812,,,,1,1,3,23552,18,2,1.7562635063933E-6,8.81930348800388E-7,,,3.36919640631095E-7,6.67001051724014E-7,5,0.972155392169952,181.829223632813,0.184229606363098,,,1.89853870868683,1.89559471607208,1.94603431224823,4499.87841796875,4499.970703125,0.0769082084298134,5,4,3,0,37.6630006574392,1,,,29.3255138397217,34.7018585205078,,,,,,,,,,,,,,,,
,3909772054.40077,1.90090325438833,4500.2197265625,1.46591828989115E-6,3.58649558507003E-9,30.9783772921194,0.137086694762688,9.83496432954139E-7,2.40620888561536E-9,8.43212083772157E-7,5.06219927910914E-7,2.00428303388551E-9,2.02270872493029E-9,1.49051713943481,5990.39990234375,,,,1,1,3,108032,18,8,8.11350554852088E-7,5.24862797993157E-7,,,9.50034376501208E-7,1.45152625918854E-6,5,0.842801034450531,165.059112548828,0.474494304178492,,,1.89090383052826,1.89247047901154,1.95664083957672,4500.19189453125,4500.24755859375,0.0766145661473274,5,4,3,0,37.6330008946657,1,,,29.3255138397217,33.2355842590332,,,,,,,,,,,,,,,,
touchdown = 16.0499997437 mm,3909773097.44014,1.90064777113214,4999.51342773438,1.55006900645162E-5,1.2262147084661E-6,13.8886148675431,3.8835205315951,3.10184545728298E-6,2.45378012674165E-7,3.01116051660076E-6,7.44551935147394E-7,5.85051635357236E-10,5.7844820591445E-10,4.99724769592285,16.6785469055176,,,,1,1,3,300,18,3,3.00586466521099E-6,7.79611876327335E-7,,,1.22524390633316E-8,5.05076211965161E-8,5,0.301961600780487,234.886840820313,0.10596816752012,,,1.88833105564117,1.88929402828217,1.95989549160004,4999.48583984375,4999.541015625,0.0766131207346916,5,4,3,0,37.5429997437,1,,,29.3255138397217,34.7018585205078,,,,,,,,,,,,,,,,
,3909774153.22619,1.90031316801906,4999.49536132812,1.31524850310766E-5,2.79320965655571E-7,12.2831036583003,1.06237390423172,2.63197818671915E-6,5.58956491462827E-8,2.57172787360055E-6,5.59932959836639E-7,6.4072408717899E-10,5.69689874020385E-10,4.99718618392944,77.4834442138672,,,,1,1,3,1400,18,9,2.56733612263183E-6,5.67969991616851E-7,,,4.3531240834227E-8,1.96989027756445E-7,5,0.810187339782715,204.584991455078,0.115417896455887,,,1.88596177101135,1.88559973239899,1.94778835773468,4999.4677734375,4999.52294921875,0.0765973702073097,5,4,3,0,37.7429994039535,1,,,30.3030319213867,35.190616607666,,,,,,,,,,,,,,,,
,3909775189.50427,1.89082300662994,4999.4677734375,,,,,,,,,,,,,,,,,3,,,,,,,,,,,,,,,,,,,,,,0.0769606158137321,6,4,3,,37.6230003528595,2,,,28.3479976654053,34.2131004333496,,,,,,,,,,,,,,,,
sample offset = 18.63 mm,3909776155.8751,1.89910352529029,4999.44946289063,2.72720290335378E-6,6.84147348885556E-8,23.3851513144227,1.34203831286149,1.82953054828305E-6,4.58956857509114E-8,1.67924837015765E-6,7.26159031083251E-7,6.40818324541234E-9,6.40672150544919E-9,1.49065721035004,1001.06951904297,,,,1,1,3,18048,18,1,1.66911939561228E-6,7.38451117415902E-7,,,2.19123778677499E-7,4.9184750139375E-7,5,0.959971785545349,183.3671875,0.163844425578505,,,1.89864754676819,1.89501297473907,1.94275915622711,4999.39404296875,4999.5048828125,0.0771360695362091,1,4,3,0,37.7230001829863,1,,,29.3255138397217,35.6793746948242,,,,,,,,,,,,,,,,
,3909777269.26098,1.90068708521774,4999.44018554687,1.43404403863744E-6,4.52685180890524E-9,34.9524407912438,0.179242096839634,9.57432228156475E-7,3.02232964759745E-9,7.84738135567212E-7,5.48509371022198E-7,1.96260573219977E-9,1.93858845261942E-9,1.49780213832855,4636.53271484375,,,,1,1,3,83968,18,7,7.57982058281387E-7,5.63462215385152E-7,,,7.87070888463859E-7,1.04583841675776E-6,5,0.912299156188965,169.261901855469,0.405521988452796,,,1.89358866214752,1.89328944683075,1.94531798362732,4999.4306640625,4999.44970703125,0.0769699439406395,5,4,3,0,37.7429994039535,1,,,27.8592376708984,34.2131004333496,,,,,,,,,,,,,,,,
,3909777828.45502,1.90205586391379,4999.42163085937,1.02501327400253E-6,3.93267533279254E-9,28.7857165154978,0.215822090994968,6.88093412595092E-7,2.64001263105894E-9,6.03063474007655E-7,3.31341199935319E-7,3.89853877272201E-9,3.6251291740219E-9,1.48964262008667,9984,,,,1,1,3,179712,18,10,5.76110846829551E-7,3.45088569464294E-7,,,1.0942353583232E-6,1.75351851794403E-6,5,0.551766812801361,162.948608398438,0.649782815109104,,,1.88224697113037,1.88550984859467,1.94906187057495,4999.37548828125,4999.4677734375,0.0764813646674156,5,4,3,0,37.71299964118,1,,,29.3255138397217,33.7243423461914,,,,,,,,,,,,,,,,