File: SQUID/ac_dc.dat
[Header]
; MPMS3 Data File (default extension .dat)
; Copyright (c) 2007, Quantum Design, Inc. All rights reserved.
TITLE,
FILEOPENTIME,3590176614.1354,10/11/2023,1:51 am
BYAPP,SQUID AC,0.9.1.0
INFO,MPMS3 Measurement Release 1.1.16 Build 347, MultiVu Release 2.3.3.2,APPNAME
INFO,0,MOMENT_UNITS
INFO,MRo54,SAMPLE_MATERIAL
INFO,MRo54 crystals under Et2O, glass,SAMPLE_COMMENT
INFO,,SAMPLE_MASS
INFO,,SAMPLE_VOLUME
INFO,,SAMPLE_MOLECULAR_WEIGHT
INFO,,SAMPLE_SIZE
INFO,,SAMPLE_SHAPE
INFO,Straw,SAMPLE_HOLDER
INFO,Standard,SAMPLE_HOLDER_DETAIL
INFO,61.3,SAMPLE_OFFSET
DATATYPE,COMMENT,1
DATATYPE,TIME,2
STARTUPAXIS,X,2
STARTUPAXIS,Y1,5
FIELDGROUP, VSM,2,3,4,5,6,8,9,10,11,14,15
FIELDGROUP, DC, 2,3,4,14,56,57,58,59,60,61,62,63,64,65,66,67,68,69
FIELDGROUP, AC, 2,3,4,11,16,17,18,19,20,21,22,23,24,25,26,27,28,29,30
STARTUPGROUP, All
[Data]
Comment,Time Stamp (sec),Temperature (K),Magnetic Field (Oe),Moment (emu),M. Std. Err. (emu),Transport Action,Averaging Time (sec),Frequency (Hz),Peak Amplitude (mm),Center Position (mm),Lockin Signal' (V),Lockin Signal (V),Range,M. Quad. Signal (emu),AC Moment (emu),AC M. Std Err. (emu),AC Phase (deg),AC Phase Std. Err. (deg),AC Susceptibility (emu/Oe),AC Suscept. Std Err. (emu/Oe),AC X' (emu/Oe),AC X' Std Err. (emu/Oe),AC X'' (emu/Oe),AC X'' Std Err. (emu/Oe),AC Drive (Oe),AC Frequency (Hz),AC Averaging Time (sec),AC Cycles,AC Range,AC Measure Type,AC Signal' (V),AC Signal'' (V),AC Trim Coil Ratio,AC Trim Coil Phase,Min. Temperature (K),Max. Temperature (K),Min. Field (Oe),Max. Field (Oe),Mass (grams),Motor Lag (deg),Pressure (Torr),Measure Count,Measurement Number,SQUID Status (code),Motor Status (code),Measure Status (code),Motor Current (amps),Motor Temp. (C),Temp. Status (code),Field Status (code),Chamber Status (code),Chamber Temp (K),Redirection State,Evercool Status,Average Temp (K),Rotation Angle (deg),Rotator state,DC Moment Fixed Ctr (emu),DC Moment Err Fixed Ctr (emu),DC Moment Free Ctr (emu),DC Moment Err Free Ctr (emu),DC Fixed Fit,DC Free Fit,DC Calculated Center (mm),DC Calculated Center Err (mm),DC Scan Length (mm),DC Scan Time (s),DC Number of Points,DC Squid Drift,DC Min V (V),DC Max V (V),DC Scans per Measure,Map 01,Map 02,Map 03,Map 04,Map 05,Map 06,Map 07,Map 08,Map 09,Map 10,Map 11,Map 12,Map 13,Map 14,Map 15,Map 16
,3590177834.36249,1.79989981651306,-0.277311772108078,,,5,,,,34.2499986290932,,,,,1.38317291271627E-6,6.21032824001702E-7,-0.070649227136333,0.303278488824782,4.6105596630856E-7,2.0701019095085E-7,4.61055615804412E-7,1.52647069059315E-7,-5.68510276129059E-10,1.39828793405035E-7,3.00001087458131,1.00057637691498,33.9804144735361,34,1,3,0.00458724116667735,5.90156359536221E-5,0.0273731667548418,178.082916259766,1.79854214191437,1.8019688129425,-0.277311772108078,-0.277311772108078,,,2.4034538269043,0,1,,,,,,1,1,1,1.79948723316193,0,0,1.80000614714115,,,,,,,,,,,,,,,,,,,,,,,,,,,,,,,,,
,3590178406.75187,1.80013728141785,-0.277311772108078,,,5,,,,34.2499986290932,,,,,3.61459090246503E-5,8.70900612870207E-8,-0.0866253232955456,0.0018967368042201,1.20486360479174E-5,2.90300197215274E-8,1.20486222773359E-5,1.79025730480672E-8,-1.82162910455882E-8,2.28525692929895E-8,3.00000007311185,3.13966870307922,14,43,1,3,0.119805600260324,0.00420740816717239,0.0271833203732967,174.643768310547,1.79889333248138,1.80102682113647,-0.277311772108078,-0.277311772108078,,,2.372389793396,0,1,,,,,,1,1,1,1.80016314983368,0,0,1.79997814519733,,,,,,,,,,,,,,,,,,,,,,,,,,,,,,,,,
,3590178783.40645,1.79987013339996,-0.277311772108078,,,5,,,,34.2499986290932,,,,,3.72025208315129E-5,2.16036240741049E-8,0.0584646638940907,0.000162745624960202,1.2400861012076E-5,7.20122006552798E-9,1.2400854556077E-5,6.914607332924E-9,1.26538473062727E-8,2.01141141083481E-9,2.99999498383903,9.82852745056152,14,137,1,3,0.122725242405588,0.0121196200408223,0.0259018335491419,163.950271606445,1.79905545711517,1.80080819129944,-0.277311772108078,-0.277311772108078,,,2.36100149154663,0,1,,,,,,1,1,1,1.79977893829346,0,0,1.79999800258213,,,,,,,,,,,,,,,,,,,,,,,,,,,,,,,,,
,3590179089.10245,1.80001270771027,-0.277311772108078,,,5,,,,34.2499986290932,,,,,3.6170155113902E-5,6.7667699652127E-9,0.0765381408444856,8.95364136693694E-5,1.20560343478538E-5,2.2554620202133E-9,1.20560235910074E-5,1.98388746719844E-9,1.61049590100252E-8,1.07298622643426E-9,3.00017021105625,30.8258380889893,14,431,1,3,0.118075169999891,0.0197116365289533,0.0191665943711996,142.140228271484,1.79880034923553,1.80146884918213,-0.277311772108078,-0.277311772108078,,,2.35420370101929,0,1,,,,,,1,1,1,1.79992401599884,0,0,1.79999994900491,,,,,,,,,,,,,,,,,,,,,,,,,,,,,,,,,
,3590179374.10908,1.79985076189041,-0.277311772108078,,,5,,,,34.2499986290932,,,,,3.68122103528707E-5,5.16606485921915E-9,-0.0510618824046141,9.38958305073831E-5,1.22707130361442E-5,1.7220182870286E-9,1.22707081632369E-5,1.28028506251706E-9,-1.09356331034706E-8,1.15161501360333E-9,3.00000580605527,96.6893615722656,14,1353,1,3,0.120845124024171,0.0144225577169293,0.009429388679564,128.475067138672,1.79891657829285,1.8008576631546,-0.277311772108078,-0.277311772108078,,,2.34960842132568,0,1,,,,,,1,1,1,1.80009949207306,0,0,1.80001249143056,,,,,,,,,,,,,,,,,,,,,,,,,,,,,,,,,
,3590179644.7074,1.79988747835159,-0.277311772108078,,,5,,,,34.2499986290932,,,,,3.70383470352154E-5,4.04831473542463E-9,-0.0650878479428836,8.18183163186491E-5,1.23462718538208E-5,1.34945531521316E-9,1.2346263887453E-5,8.95110057761804E-10,-1.40253278526665E-8,1.00985525311834E-9,2.99996205119631,303.2802734375,14,4245,1,3,0.121693071005758,0.0138558025051869,0.0058465083129704,126.771408081055,1.7990779876709,1.80098509788513,-0.277311772108078,-0.277311772108078,,,2.34580659866333,0,1,,,,,,1,1,1,1.79986763000488,0,0,1.80000852847445,,,,,,,,,,,,,,,,,,,,,,,,,,,,,,,,,
,3590179937.29025,1.79941689968109,-0.277311772108078,,,5,,,,34.2499986290932,,,,,3.41077440172641E-5,8.27431841233577E-9,0.328248087206697,0.000186555066738784,1.13695527363735E-5,2.75818006312527E-9,1.13693661536878E-5,1.78446423107038E-9,6.51359237044545E-8,2.1031511283434E-9,2.99991959297981,950.425842285156,14,13305,100,3,0.108765935560193,0.0305344735809081,0.00761943962424994,90.4678955078125,1.79363238811493,1.8077609539032,-0.277311772108078,-0.277311772108078,,,2.33954238891602,0,1,,,,,,1,1,1,1.79936122894287,0,0,1.79999857166639,,,,,,,,,,,,,,,,,,,,,,,,,,,,,,,,,
,3590180698.07515,1.80001896619797,199.803131103516,,,5,,,,34.2499986290932,,,,,3.70824927311476E-5,7.5602666037975E-8,-0.0467191075076563,0.000816495660722064,1.23608427174597E-5,2.52009127512372E-8,1.23608386082162E-5,2.30912782367933E-8,-1.00790578418952E-8,1.00935064713145E-8,2.99999713439996,2.39918065071106,14.1715047551435,33,1,3,0.122941476004389,0.00347261267487237,0.027319660410285,175.842727661133,1.79868698120117,1.80155563354492,199.803131103516,199.803131103516,,,2.33477997779846,0,1,,,,,,1,1,1,1.80001080036163,0,0,1.80001532919002,,,,,,,,,,,,,,,,,,,,,,,,,,,,,,,,,
,3590181088.14932,1.79997956752777,199.803131103516,,,5,,,,34.2499986290932,,,,,3.58941774569724E-5,7.27023007364473E-8,0.164908495642152,0.000958457636888239,1.19646209475969E-5,2.42338878324351E-8,1.19645713900908E-5,2.13542420279798E-8,3.44364791615107E-8,1.14576466556404E-8,3.00002629537391,7.40717935562134,14,103,1,3,0.118625483292912,0.00958980116412457,0.0265526585280895,167.61149597168,1.79925656318665,1.80119633674622,199.803131103516,199.803131103516,,,2.33323669433594,0,1,,,,,,1,1,1,1.79991388320923,0,0,1.8000022266688,,,,,,,,,,,,,,,,,,,,,,,,,,,,,,,,,
,3590181411.3034,1.80004966259003,199.803131103516,,,5,,,,34.2499986290932,,,,,3.69029204011107E-5,1.32356366380935E-8,0.531715793032989,0.000132844907137806,1.23018996511955E-5,4.41221106545846E-9,1.23013699232035E-5,4.11052766206392E-9,1.14162343124037E-7,1.60348645942564E-9,2.99977413630784,23.2072830200195,14,324,1,3,0.120508858331824,0.0201955833160167,0.0216070245951414,148.136810302734,1.79909908771515,1.80118668079376,199.803131103516,199.803131103516,,,2.33248734474182,0,1,,,,,,1,1,1,1.80002439022064,0,0,1.80000449905933,,,,,,,,,,,,,,,,,,,,,,,,,,,,,,,,,
,3590181697.13241,1.79998314380646,199.803131103516,,,5,,,,34.2499986290932,,,,,3.59207176147565E-5,5.93717815806759E-9,0.818749375435194,0.000111299727914558,1.19736631725063E-5,1.97907436656161E-9,1.19724406795947E-5,1.46518100446664E-9,1.71096295168052E-7,1.33040594276009E-9,2.99997729159753,72.6609039306641,14,1017,1,3,0.117453943963509,0.0176572797297814,0.0114338286221027,129.625457763672,1.7988772392273,1.80136954784393,199.803131103516,199.803131103516,,,2.33118510246277,0,1,,,,,,1,1,1,1.80001223087311,0,0,1.79997556209564,,,,,,,,,,,,,,,,,,,,,,,,,,,,,,,,,
,3590181968.12628,1.79982429742813,199.803131103516,,,5,,,,34.2499986290932,,,,,3.60844171726759E-5,6.5774108612222E-9,1.86734100626346,0.000123838205200608,1.20287802869167E-5,2.19258716935387E-9,1.2022392430317E-5,1.61101368392584E-9,3.9196357276177E-7,1.48730407295176E-9,2.99984007621485,227.636947631836,14,3186,1,3,0.118180037254536,0.0163419566803724,0.00625520944595337,128.506881713867,1.79827356338501,1.80201351642609,199.803131103516,199.803131103516,,,2.33120083808899,0,1,,,,,,1,1,1,1.80003726482391,0,0,1.80001798904303,,,,,,,,,,,,,,,,,,,,,,,,,,,,,,,,,
,3590182252.48096,1.79987305402756,199.803131103516,,,5,,,,34.2499986290932,,,,,3.50594502412305E-5,1.15466653050784E-8,2.37449937546262,0.000217905678251487,1.1686833970526E-5,3.84900388925632E-9,1.1676799289465E-5,2.91933828742555E-9,4.84196869249487E-7,2.508444717964E-9,2.99991001238229,714.122497558594,14,9997,1,3,0.112490461785255,0.0285735427886103,0.00653303228318691,103.846038818359,1.7951295375824,1.80671858787537,199.803131103516,199.803131103516,,,2.32907319068909,0,1,,,,,,1,1,1,1.79973542690277,0,0,1.80009941087253,,,,,,,,,,,,,,,,,,,,,,,,,,,,,,,,,
,3590182963.64637,1.79994612932205,399.518005371094,,,5,,,,34.2499986290932,,,,,3.5986871950072E-5,7.06959791429664E-8,0.0554915930202591,0.00148362279927803,1.19956491593279E-5,2.35653758390214E-8,1.19956435332875E-5,1.54463534768916E-8,1.1617916411195E-8,1.77971093917315E-8,2.99999370372453,1.80150997638702,18.8730567388741,34,1,3,0.119326074797662,0.0028487284223981,0.0273880511522293,176.823638916016,1.79941856861114,1.8013664484024,399.518005371094,399.518005371094,,,2.32759261131287,0,1,,,,,,1,1,1,1.80007994174957,0,0,1.80000968711583,,,,,,,,,,,,,,,,,,,,,,,,,,,,,,,,,
,3590183385.66914,1.80028653144836,399.518005371094,,,5,,,,34.2499986290932,,,,,3.63704333064302E-5,3.91571777745279E-8,0.39487792049907,0.000417504061461285,1.21234034924613E-5,1.30523126240212E-8,1.21231155715011E-5,1.20359170773797E-8,8.35528638098819E-8,5.04970939179897E-9,3.00001838007342,5.59955549240112,14,78,1,3,0.120328854059869,0.00822918996811426,0.026892876252532,170.559631347656,1.79920363426209,1.80084013938904,399.518005371094,399.518005371094,,,2.32723879814148,0,1,,,,,,1,1,1,1.80003881454468,0,0,1.79999562968378,,,,,,,,,,,,,,,,,,,,,,,,,,,,,,,,,
,3590183728.61384,1.80000168085098,399.518005371094,,,5,,,,34.2499986290932,,,,,3.62127332922939E-5,1.65655440247942E-8,1.071421148501,0.000155840967151698,1.207151187933E-5,5.5221228364284E-9,1.20694013364546E-5,5.21213886991597E-9,2.2572202460507E-7,1.8241296613221E-9,2.99985069428634,17.3889331817627,14,243,1,3,0.118441457187642,0.0190228749864027,0.0235977061092854,154.153594970703,1.79879689216614,1.80087995529175,399.518005371094,399.518005371094,,,2.32672595977783,0,1,,,,,,1,1,1,1.79999506473541,0,0,1.79996965328852,,,,,,,,,,,,,,,,,,,,,,,,,,,,,,,,,
,3590184018.15785,1.79957503080368,399.518005371094,,,5,,,,34.2499986290932,,,,,3.54153603561089E-5,5.1352557124664E-9,2.25553820212899,7.43711339142035E-5,1.18058263075657E-5,1.71185430210808E-9,1.17966795869045E-5,1.48050919100623E-9,4.64634833305864E-7,8.59382154220135E-10,2.9998205490634,54.6175918579102,14,764,1,3,0.115026230569768,0.022104597484252,0.0138980932533741,132.466156005859,1.79907143115997,1.80137813091278,399.518005371094,399.518005371094,,,2.32654476165771,0,1,,,,,,1,1,1,1.79957437515259,0,0,1.80000532184328,,,,,,,,,,,,,,,,,,,,,,,,,,,,,,,,,
,3590184294.11309,1.79998242855072,399.518005371094,,,5,,,,34.2499986290932,,,,,3.45752037996089E-5,6.63272621704013E-9,5.07496136467193,9.89246168260216E-5,1.15257425700036E-5,2.21103815780786E-9,1.14805595579514E-5,1.91699152462279E-9,1.01955579853367E-6,1.10174099942171E-9,2.99982440086704,171.026702880859,14,2394,1,3,0.11220790049336,0.0217942223755299,0.00693508749827743,128.718414306641,1.79893183708191,1.80138289928436,399.518005371094,399.518005371094,,,2.32696390151978,0,1,,,,,,1,1,1,1.80029702186584,0,0,1.80001889936852,,,,,,,,,,,,,,,,,,,,,,,,,,,,,,,,,
,3590184573.28416,1.79996007680893,399.518005371094,,,5,,,,34.2499986290932,,,,,3.07654904683929E-5,5.21278220295091E-9,7.31523603688626,0.000111822101882854,1.02546385715982E-5,1.7375051276572E-9,1.01711721574094E-5,1.34170686431314E-9,1.30570639059833E-6,1.10396864035626E-9,3.00015356500253,536.572814941406,14,7512,1,3,0.0975077987744189,0.0292575226403801,0.00599520793184638,114.300811767578,1.79745602607727,1.80259072780609,399.518005371094,399.518005371094,,,2.32626128196716,0,1,,,,,,1,1,1,1.80012798309326,0,0,1.80000793232637,,,,,,,,,,,,,,,,,,,,,,,,,,,,,,,,,
,3590185220.74238,1.80008667707443,599.774963378906,,,5,,,,34.2499986290932,,,,,3.61413302320457E-5,6.29295841073143E-8,-0.00889638135429105,0.00128245963956008,1.20471486467691E-5,2.09765951931664E-8,1.20471485015459E-5,1.41885832971034E-8,-1.87057457065165E-9,1.54499724892678E-8,2.99999039538194,1.33032166957855,25.5577284633507,33,1,3,0.11985573026361,0.0021441178542577,0.027449594810605,177.578964233398,1.79905319213867,1.80096507072449,599.774963378906,599.774963378906,,,2.32426905632019,0,1,,,,,,1,1,1,1.80006325244904,0,0,1.79999663859983,,,,,,,,,,,,,,,,,,,,,,,,,,,,,,,,,
,3590185700.73543,1.79952037334442,599.774963378906,,,5,,,,34.2499986290932,,,,,3.59721898629593E-5,7.88420683284514E-8,0.467427941262497,0.000593406053679122,1.19907337258688E-5,2.62806977091119E-8,1.1990334703329E-5,2.53095617872935E-8,9.78211982762864E-8,7.07821688088834E-9,2.99999905638409,4.2035231590271,14,58,1,3,0.119113981624682,0.00668130121746049,0.0271741598844528,172.917877197266,1.79920661449432,1.80109143257141,599.774963378906,599.774963378906,,,2.32348990440369,0,1,,,,,,1,1,1,1.79974257946014,0,0,1.80000248457256,,,,,,,,,,,,,,,,,,,,,,,,,,,,,,,,,
,3590186064.63859,1.79993003606796,599.774963378906,,,5,,,,34.2499986290932,,,,,3.46364253485335E-5,2.21674451092646E-8,1.47609202510963,0.000193610263545245,1.15450461874085E-5,7.38887385369686E-9,1.15412150894106E-5,7.07176277324774E-9,2.97398267239327E-7,2.14140797251541E-9,3.0001114578744,13.0976734161377,14,183,1,3,0.113569732124284,0.0166518026974235,0.0250292792916298,159.491821289062,1.79896569252014,1.80128633975983,599.774963378906,599.774963378906,,,2.3229296207428,0,1,,,,,,1,1,1,1.79954016208649,0,0,1.79999670386314,,,,,,,,,,,,,,,,,,,,,,,,,,,,,,,,,
,3590186355.43233,1.79979938268662,599.774963378906,,,5,,,,34.2499986290932,,,,,3.39011862604953E-5,7.89579318479127E-9,3.51196023986597,0.000131539677779927,1.12993192890091E-5,2.63168042408305E-9,1.12780995409779E-5,2.19926349285985E-9,6.92161208655997E-7,1.44533108438026E-9,3.00028571574848,41.0320358276367,14,574,1,3,0.109379779144279,0.0248164600783184,0.0166207551956177,136.888748168945,1.79896354675293,1.80118191242218,599.774963378906,599.774963378906,,,2.32351016998291,0,1,,,,,,1,1,1,1.80022692680359,0,0,1.79999979053225,,,,,,,,,,,,,,,,,,,,,,,,,,,,,,,,,
,3590186635.60756,1.79973745346069,599.774963378906,,,5,,,,34.2499986290932,,,,,3.31058429476839E-5,4.8012295384503E-9,7.69034783290285,0.000100267162286042,1.10345314800729E-5,1.60030114831412E-9,1.09352842252704E-5,1.1688962372018E-9,1.47663262095604E-6,1.09299833117484E-9,3.00020377008932,128.495071411133,14,1798,1,3,0.106229304414579,0.0263413352199581,0.00805302243679762,128.337936401367,1.79908633232117,1.80117011070251,599.774963378906,599.774963378906,,,2.32365393638611,0,1,,,,,,1,1,1,1.79961156845093,0,0,1.79999725565766,,,,,,,,,,,,,,,,,,,,,,,,,,,,,,,,,
,3590186916.62795,1.79972559213638,599.774963378906,,,5,,,,34.2499986290932,,,,,2.76462507421521E-5,4.5487943958899E-9,13.0078537818917,0.000127369458533463,9.21551559058565E-6,1.51628103443979E-9,8.97903827806209E-6,9.82062756210196E-10,2.07427076376807E-6,1.15527525649372E-9,2.99996787704367,403.538238525391,14,5649,1,3,0.085553891409985,0.0323028092217585,0.00582841038703918,121.680206298828,1.79889798164368,1.80134928226471,599.774963378906,599.774963378906,,,2.32350707054138,0,1,,,,,,1,1,1,1.79976165294647,0,0,1.8000303639306,,,,,,,,,,,,,,,,,,,,,,,,,,,,,,,,,
,3590187405.034,1.79997110366821,799.893188476563,,,5,,,,34.2499986290932,,,,,1.25248184613806E-6,1.3166860314712E-6,-0.280935626561976,0.660218326807952,4.1749393363335E-7,4.38895327971407E-7,4.17488914974517E-7,3.41538287602489E-7,-2.04706962457152E-9,2.75645981317864E-7,3.00000010835609,1.00057637691498,33.9804144735361,34,10,3,0.00415414770386086,4.05785809961383E-5,0.000268082832917571,89.4043579101562,1.79890990257263,1.80165040493011,799.893188476563,799.893188476563,,,2.32127928733826,0,1,,,,,,1,1,1,1.79975867271423,0,0,1.79998990802265,,,,,,,,,,,,,,,,,,,,,,,,,,,,,,,,,
,3590188002.28954,1.8000351190567,799.893188476563,,,5,,,,34.2499986290932,,,,,3.51686397927231E-5,6.56291275470498E-8,0.378326434764254,0.00147098917525709,1.17228881261851E-5,2.18763911424401E-8,1.17226325671983E-5,1.34593097248892E-8,7.74061593946932E-8,1.72459697073414E-8,2.99999790274958,3.13966870307922,14,43,1,3,0.116531888829835,0.00510651110730075,0.0273023638874292,174.613433837891,1.79904556274414,1.80120050907135,799.893188476563,799.893188476563,,,2.3204391002655,0,1,,,,,,1,1,1,1.79985892772675,0,0,1.7999905713714,,,,,,,,,,,,,,,,,,,,,,,,,,,,,,,,,
,3590188377.68977,1.799984395504,799.893188476563,,,5,,,,34.2499986290932,,,,,3.46218531219159E-5,1.50209338088052E-8,1.69135343843138,0.00022415666730475,1.15405039229638E-5,5.00692857013375E-9,1.15354760219833E-5,4.29855907193863E-9,3.40622580272276E-7,2.56743522050231E-9,3.00002957869317,9.82852745056152,14,137,1,3,0.113841191076888,0.0145947948961846,0.0260413996875286,164.067230224609,1.79896533489227,1.80127882957458,799.893188476563,799.893188476563,,,2.32080030441284,0,1,,,,,,1,1,1,1.799884557724,0,0,1.80000956190957,,,,,,,,,,,,,,,,,,,,,,,,,,,,,,,,,
,3590188681.67076,1.79972612857819,799.893188476563,,,5,,,,34.2499986290932,,,,,3.38615310063634E-5,1.54338899289902E-8,4.37712025610153,0.000322722983349903,1.12876161834764E-5,5.14483015265093E-9,1.12546936915445E-5,3.66240452314296E-9,8.61480710744659E-7,3.61331847592877E-9,2.99988327525987,30.8258380889893,14,431,1,3,0.108833522190221,0.0267543030877218,0.0193541496992111,142.410293579102,1.79906058311462,1.80104494094849,799.893188476563,799.893188476563,,,2.32092213630676,0,1,,,,,,1,1,1,1.79992818832397,0,0,1.80000703267648,,,,,,,,,,,,,,,,,,,,,,,,,,,,,,,,,
,3590188966.61513,1.79989111423492,799.893188476563,,,5,,,,34.2499986290932,,,,,3.16326395924207E-5,5.61307990460112E-9,9.29522008362746,0.000141913468000265,1.05440272549684E-5,1.87099364014537E-9,1.04055756872334E-5,1.10894790813047E-9,1.703087012097E-6,1.5069345501771E-9,3.00005290459726,96.6893615722656,14,1353,1,3,0.100438762538007,0.0291514452368932,0.0095513891428709,128.424743652344,1.79923236370087,1.80113852024078,799.893188476563,799.893188476563,,,2.32112669944763,0,1,,,,,,1,1,1,1.79990220069885,0,0,1.79999549218587,,,,,,,,,,,,,,,,,,,,,,,,,,,,,,,,,
,3590189241.29866,1.80000764131546,799.893188476563,,,5,,,,34.2499986290932,,,,,2.60940424345907E-5,5.62884603278473E-9,17.367389802427,0.000167061549511667,8.69843014647742E-6,1.87637174823282E-9,8.30187197459123E-6,1.29334238368916E-9,2.5964608086093E-6,1.35942503144511E-9,2.99985652527864,303.2802734375,14,4245,1,3,0.07885627032862,0.0350438871696147,0.0059248274192214,126.206787109375,1.79897475242615,1.80110931396484,799.893188476563,799.893188476563,,,2.3208703994751,0,1,,,,,,1,1,1,1.79989647865295,0,0,1.79999107036038,,,,,,,,,,,,,,,,,,,,,,,,,,,,,,,,,
,3590189539.90657,1.80001300573349,799.893188476563,,,5,,,,34.2499986290932,,,,,1.77495562100002E-5,7.0901401273516E-9,16.0934384946806,0.000361076818801005,5.91634738658131E-6,2.36331159588758E-9,5.68449109209562E-6,1.46198092551699E-9,1.64003884789143E-6,1.85683964646417E-9,3.0000868864221,950.425842285156,14,13305,100,3,0.0501406328762585,0.030699401493434,0.00775299919769168,89.8640747070312,1.79428672790527,1.80627250671387,799.893188476563,799.893188476563,,,2.31936430931091,0,1,,,,,,1,1,1,1.8002450466156,0,0,1.80001935904676,,,,,,,,,,,,,,,,,,,,,,,,,,,,,,,,,
,3590190266.56326,1.80026823282242,999.923217773437,,,5,,,,34.2499986290932,,,,,3.26276840834983E-5,5.68353817528114E-8,0.501309586745439,0.00121510915677834,1.08758710810696E-5,1.89450861178216E-8,1.08754547890939E-5,1.35748890885296E-8,9.51572510154232E-8,1.32150926688312E-8,3.00000651352788,2.39918065071106,14.1715047551435,33,1,3,0.108140711507102,0.00415219874430839,0.0273732077330351,175.891845703125,1.79887640476227,1.80122661590576,999.923217773437,999.923217773437,,,2.31926250457764,0,1,,,,,,1,1,1,1.80048787593842,0,0,1.79999276324435,,,,,,,,,,,,,,,,,,,,,,,,,,,,,,,,,
,3590190658.67746,1.80002272129059,999.923217773437,,,5,,,,34.2499986290932,,,,,3.35387596112841E-5,2.94168954380584E-8,1.67467729267989,0.000706462777500487,1.1179478880359E-5,9.80553738680474E-9,1.11747038334335E-5,5.79933477073164E-9,3.26714357565006E-7,7.90672369954892E-9,3.00002888955832,7.40717935562134,14,103,1,3,0.110564882214526,0.0119417666346381,0.026587225496769,168.158157348633,1.79939258098602,1.8007185459137,999.923217773437,999.923217773437,,,2.31939125061035,0,1,,,,,,1,1,1,1.80002534389496,0,0,1.8000089512931,,,,,,,,,,,,,,,,,,,,,,,,,,,,,,,,,
,3590190981.8399,1.79999983310699,999.923217773437,,,5,,,,34.2499986290932,,,,,3.2561445592172E-5,1.11698840992586E-8,4.79610483244873,0.00021247247643265,1.08529953670003E-5,3.72301346498962E-9,1.08149940992627E-5,2.96740148197523E-9,9.07420006966557E-7,2.24841226319046E-9,3.00022661865116,23.2072830200195,14,324,1,3,0.10470219771432,0.0257382455221795,0.021752554923296,148.401382446289,1.79906141757965,1.80147624015808,999.923217773437,999.923217773437,,,2.31872224807739,0,1,,,,,,1,1,1,1.80013203620911,0,0,1.79999416478923,,,,,,,,,,,,,,,,,,,,,,,,,,,,,,,,,
,3590191269.50975,1.79994702339172,999.923217773437,,,5,,,,34.2499986290932,,,,,2.9995737597328E-5,8.67953356260024E-9,10.137482936573,0.000168574438738082,9.99940672893682E-6,2.89341730731866E-9,9.84329843376164E-6,2.47428245294198E-9,1.76000308937588E-6,1.49993001748568E-9,2.99975172632239,72.6609039306641,14,1017,1,3,0.0943853982477046,0.0304873922559586,0.011591162532568,129.703720092773,1.7985702753067,1.80127596855164,999.923217773437,999.923217773437,,,2.31930136680603,0,1,,,,,,1,1,1,1.799919962883,0,0,1.79999993698938,,,,,,,,,,,,,,,,,,,,,,,,,,,,,,,,,
,3590191548.76939,1.79990130662918,999.923217773437,,,5,,,,34.2499986290932,,,,,2.51006430634375E-5,5.01253212787395E-9,19.6545830720054,0.000167675850385748,8.36721477153156E-6,1.67091069169523E-9,7.87971955245962E-6,8.94605014247822E-10,2.81430325436361E-6,1.41124923670629E-9,2.99988033638618,227.636947631836,14,3186,1,3,0.0747878509525715,0.0359811894203439,0.00634835148230195,128.270202636719,1.7987334728241,1.80103492736816,999.923217773437,999.923217773437,,,2.319979429245,0,1,,,,,,1,1,1,1.79983961582184,0,0,1.8000255788582,,,,,,,,,,,,,,,,,,,,,,,,,,,,,,,,,
,3590191833.8095,1.79983329772949,999.923217773437,,,5,,,,34.2499986290932,,,,,1.7333676053781E-5,3.1387437908376E-8,20.6200905953205,0.00184094382397807,5.77767288726815E-6,1.04620825058329E-8,5.40753266364446E-6,9.01704732475654E-9,2.03472221295481E-6,5.30547150609209E-9,3.00011378144617,714.122497558594,14,9997,1,3,0.0483821796097028,0.0308578010183109,0.00662056123837829,103.540771484375,1.79579508304596,1.80443644523621,999.923217773437,999.923217773437,,,2.31886005401611,0,1,,,,,,1,1,1,1.80004441738129,0,0,1.79994117296659,,,,,,,,,,,,,,,,,,,,,,,,,,,,,,,,,
,3590192566.83633,1.7999455332756,1500.05493164062,,,5,,,,34.2499986290932,,,,,2.96722176295366E-5,9.49461661190465E-8,0.419353179387991,0.00163999195595977,9.8906960392834E-6,3.16485839010565E-8,9.8904311224616E-6,2.71793364316431E-8,7.23902848408474E-8,1.62147011713992E-8,3.00001309429446,1.80150997638702,18.8730567388741,34,1,3,0.0983748143027764,0.00305148231235696,0.0275055132806301,176.866394042969,1.799241065979,1.80085825920105,1500.05493164062,1500.05493164062,,,2.31734919548035,0,1,,,,,,1,1,1,1.7999724149704,0,0,1.79998434924368,,,,,,,,,,,,,,,,,,,,,,,,,,,,,,,,,
,3590192990.12669,1.80005156993866,1500.05493164062,,,5,,,,34.2499986290932,,,,,2.90430302703865E-5,6.04475390287585E-8,2.11862313915533,0.00142385822736848,9.68101363164732E-6,2.01491870472494E-8,9.67439598599078E-6,1.47045513713534E-8,3.57892780573658E-7,1.37755547123255E-8,2.99999890253688,5.59955549240112,14,78,1,3,0.095844174031729,0.00953490831723023,0.0272109918296337,170.258148193359,1.79887282848358,1.8011816740036,1500.05493164062,1500.05493164062,,,2.31746625900269,0,1,,,,,,1,1,1,1.79995226860046,0,0,1.80000309192616,,,,,,,,,,,,,,,,,,,,,,,,,,,,,,,,,
,3590193332.54643,1.80016183853149,1500.05493164062,,,5,,,,34.2499986290932,,,,,2.88641643551201E-5,1.17897966207451E-8,6.233839097493,0.00021170497640385,9.62161988921245E-6,3.93002687555055E-9,9.56472730636528E-6,3.44466967956986E-9,1.04477789379317E-6,1.89192019948034E-9,2.9999277343602,17.3889331817627,14,243,1,3,0.0926464117317146,0.0236703218428702,0.0237389709800482,154.36296081543,1.79877150058746,1.80127954483032,1500.05493164062,1500.05493164062,,,2.31720280647278,0,1,,,,,,1,1,1,1.79995775222778,0,0,1.80001337495115,,,,,,,,,,,,,,,,,,,,,,,,,,,,,,,,,
,3590193622.14289,1.79995727539062,1500.05493164062,,,5,,,,34.2499986290932,,,,,2.56585375746666E-5,1.12718197397999E-8,12.9923784590205,0.000302522648614336,8.55272777178035E-6,3.75722137111475E-9,8.3337777644249E-6,2.96651455288323E-9,1.92283657947314E-6,2.30575450538288E-9,3.00004142062451,54.6175918579102,14,764,1,3,0.0788747665260607,0.031324104854772,0.0140434140339494,132.640151977539,1.79879295825958,1.8019186258316,1500.05493164062,1500.05493164062,,,2.31810736656189,0,1,,,,,,1,1,1,1.79998409748077,0,0,1.79997953857694,,,,,,,,,,,,,,,,,,,,,,,,,,,,,,,,,
,3590193893.60273,1.80007290840149,1500.05493164062,,,5,,,,34.2499986290932,,,,,2.06146705622826E-5,5.34243553663575E-9,23.5804103348658,0.00022469109213221,6.87137617357576E-6,1.78076502092976E-9,6.29761321904155E-6,1.01558746585533E-9,2.7487957840003E-6,1.46277344758665E-9,3.00007888398796,171.026702880859,14,2394,1,3,0.0592953383576918,0.0336051138917419,0.00705573335289955,128.647811889648,1.7989068031311,1.80084371566772,1500.05493164062,1500.05493164062,,,2.31868696212769,0,1,,,,,,1,1,1,1.80040955543518,0,0,1.79999986428481,,,,,,,,,,,,,,,,,,,,,,,,,,,,,,,,,
,3590194180.73645,1.79995739459991,1500.05493164062,,,5,,,,34.2499986290932,,,,,1.33435631291053E-5,9.11423925459375E-9,28.5772301883497,0.000838458658006698,4.44786427955564E-6,3.03808651584276E-9,3.90599495024866E-6,2.06254962086624E-9,2.12760430954137E-6,2.2306632957957E-9,2.99999332048827,536.572814941406,14,7512,1,3,0.0347920147576426,0.0271903052087875,0.00605901191011071,114.220199584961,1.79845833778381,1.80191254615784,1500.05493164062,1500.05493164062,,,2.31756973266602,0,1,,,,,,1,1,1,1.80003142356873,0,0,1.79999394174935,,,,,,,,,,,,,,,,,,,,,,,,,,,,,,,,,
,3590194740.92631,1.79979956150055,2000.28759765625,,,5,,,,34.2499986290932,,,,,2.63820145417888E-5,8.32066084079146E-8,0.0542003512780123,0.00148037111750005,8.79397068857276E-6,2.7735428402396E-8,8.79396675385194E-6,2.44906735433048E-8,8.31887153664791E-9,1.30177147787047E-8,3.00001165299204,1.33032166957855,25.5577284633507,33,1,3,0.0874944768870813,0.00174952551228992,0.0275837816298008,177.642150878906,1.79933869838715,1.80115032196045,2000.28759765625,2000.28759765625,,,2.31679463386536,0,1,,,,,,1,1,1,1.79997515678406,0,0,1.79999984819678,,,,,,,,,,,,,,,,,,,,,,,,,,,,,,,,,
,3590195216.92103,1.7999969124794,2000.28759765625,,,5,,,,34.2499986290932,,,,,2.47922680933285E-5,4.64760643240853E-8,2.18321878117966,0.00117787832046947,8.26409234900775E-6,1.54920270362848E-8,8.25809358371051E-6,1.20643699763334E-8,3.14821720355918E-7,9.71873853785171E-9,2.99999891655437,4.2035231590271,14,58,1,3,0.0819189825122539,0.00714363977184949,0.0273190755397081,172.914047241211,1.79891419410706,1.80133664608002,2000.28759765625,2000.28759765625,,,2.31656908988953,0,1,,,,,,1,1,1,1.79974007606506,0,0,1.80000903457403,,,,,,,,,,,,,,,,,,,,,,,,,,,,,,,,,
,3590195581.71466,1.80003833770752,2000.28759765625,,,5,,,,34.2499986290932,,,,,2.43122735054435E-5,2.03609035960232E-8,6.52291697110532,0.000614490900006269,8.10423523554541E-6,6.78708851780107E-9,8.05177244901229E-6,4.62826798958166E-9,9.20646067923174E-7,4.96424273833189E-9,2.99994666971279,13.0976734161377,14,183,1,3,0.0783680914059661,0.0187360240212554,0.0252180844545364,159.666976928711,1.79884052276611,1.80154550075531,2000.28759765625,2000.28759765625,,,2.31692242622375,0,1,,,,,,1,1,1,1.79985523223877,0,0,1.80003295935594,,,,,,,,,,,,,,,,,,,,,,,,,,,,,,,,,
,3590195872.70717,1.79992997646332,2000.28759765625,,,5,,,,34.2499986290932,,,,,2.16682887991111E-5,2.0973404032672E-8,13.9699219280093,0.000723678039215779,7.22206471660995E-6,6.99045885237505E-9,7.00845476351129E-6,5.0919670733798E-9,1.74349665864841E-6,4.78940354223412E-9,3.00029003468723,41.0320358276367,14,574,1,3,0.065847704497678,0.0283564026961516,0.0167844239622354,137.108505249023,1.79933738708496,1.80107355117798,2000.28759765625,2000.28759765625,,,2.31714558601379,0,1,,,,,,1,1,1,1.79998016357422,0,0,1.80000746921754,,,,,,,,,,,,,,,,,,,,,,,,,,,,,,,,,
,3590196152.98704,1.8000585436821,2000.28759765625,,,5,,,,34.2499986290932,,,,,1.75472410950551E-5,7.09115228650123E-9,23.9544019218576,0.000357912720351903,5.84947186391594E-6,2.3638756405029E-9,5.34565020853043E-6,1.71959900443012E-9,2.37494103816974E-6,1.62200101964392E-9,2.99979921320761,128.495071411133,14,1798,1,3,0.0501166686066645,0.0292245704183537,0.00815658457577229,128.397445678711,1.79877626895905,1.80102813243866,2000.28759765625,2000.28759765625,,,2.31699872016907,0,1,,,,,,1,1,1,1.7995890378952,0,0,1.80000134489753,,,,,,,,,,,,,,,,,,,,,,,,,,,,,,,,,
,3590196427.06479,1.80007964372635,2000.28759765625,,,5,,,,34.2499986290932,,,,,1.13719836118152E-5,8.85744448559005E-9,31.5132016272282,0.00112052908410209,3.7908539814102E-6,2.95263164628841E-9,3.23177789555007E-6,2.26050379617527E-9,1.98146045688716E-6,1.89951473438376E-9,2.9998474400707,403.538238525391,14,5649,1,3,0.0291336948290739,0.0238005516771158,0.00589152052998543,121.704483032227,1.79856193065643,1.80186140537262,2000.28759765625,2000.28759765625,,,2.31737923622131,0,1,,,,,,1,1,1,1.80015635490417,0,0,1.80000820670809,,,,,,,,,,,,,,,,,,,,,,,,,,,,,,,,,
,3590196876.90053,1.80026352405548,2500.26806640625,,,5,,,,34.2499986290932,,,,,7.80334410221196E-7,1.01357273799239E-6,-0.277365854933952,1.02560249848763,2.60110666109081E-7,3.3785653506485E-7,2.6010761829799E-7,2.07326806821254E-7,-1.25917713502526E-9,2.66763253577641E-7,3.00000927256843,1.00057637691498,33.9804144735361,34,1,3,0.00258838194229045,2.86028260603095E-5,0.0277003925293684,178.085754394531,1.79897522926331,1.80102074146271,2500.26806640625,2500.26806640625,,,2.31674814224243,0,1,,,,,,1,1,1,1.79998004436493,0,0,1.79999362553662,,,,,,,,,,,,,,,,,,,,,,,,,,,,,,,,,
,3590197459.49647,1.79996359348297,2500.26806640625,,,5,,,,34.2499986290932,,,,,2.10668007709951E-5,9.77503607426224E-8,1.93906044876136,0.00299840324478159,7.02225901045569E-6,3.25834168634306E-8,7.0182379293976E-6,2.48811533683536E-8,2.37608872500746E-7,2.10382333278381E-8,3.00000338062552,3.13966870307922,14,43,1,3,0.069696778174589,0.0050445354376518,0.0274374037981033,174.654525756836,1.79920017719269,1.80082845687866,2500.26806640625,2500.26806640625,,,2.31585454940796,0,1,,,,,,1,1,1,1.79994368553162,0,0,1.80001445845062,,,,,,,,,,,,,,,,,,,,,,,,,,,,,,,,,
,3590197836.25058,1.79986047744751,2500.26806640625,,,5,,,,34.2499986290932,,,,,2.07478752415249E-5,2.92986213710757E-8,5.91556020292318,0.000816292900534254,6.91613203895617E-6,9.76645230429145E-9,6.87930269781672E-6,8.06667723707822E-9,7.1279504213176E-7,5.50566153743616E-9,2.99992468690004,9.82852745056152,14,137,1,3,0.0673820059955867,0.0138311839918784,0.0262016467750072,164.245758056641,1.79898715019226,1.80081570148468,2500.26806640625,2500.26806640625,,,2.31520485877991,0,1,,,,,,1,1,1,1.79995536804199,0,0,1.79997481134805,,,,,,,,,,,,,,,,,,,,,,,,,,,,,,,,,
,3590198141.68247,1.79987597465515,2500.26806640625,,,5,,,,34.2499986290932,,,,,1.90338366767503E-5,2.33359749682185E-8,13.4972143971674,0.000969743130194077,6.34406372907991E-6,7.77798585187124E-9,6.16884873874732E-6,4.96572856287223E-9,1.48069235058567E-6,5.98653520425497E-9,3.00025937468173,30.8258380889893,14,431,1,3,0.0579948949598208,0.0246184573792208,0.0195486210286617,142.697616577148,1.79860925674438,1.801429271698,2500.26806640625,2500.26806640625,,,2.316086769104,0,1,,,,,,1,1,1,1.79959630966187,0,0,1.8000151515007,,,,,,,,,,,,,,,,,,,,,,,,,,,,,,,,,
,3590198426.6517,1.79998779296875,2500.26806640625,,,5,,,,34.2499986290932,,,,,1.48925435693136E-5,1.0485118412052E-8,22.7134081312434,0.000611647444164092,4.96379435500731E-6,3.49476711906814E-9,4.5788409639911E-6,2.35664353405397E-9,1.91662980913881E-6,2.58062559661829E-9,3.00023379378933,96.6893615722656,14,1353,1,3,0.0427852711258423,0.0243771944096284,0.00967298820614815,128.55908203125,1.79892444610596,1.8011132478714,2500.26806640625,2500.26806640625,,,2.31701469421387,0,1,,,,,,1,1,1,1.80000448226929,0,0,1.80001940046038,,,,,,,,,,,,,,,,,,,,,,,,,,,,,,,,,
,3590198701.10987,1.79988974332809,2500.26806640625,,,5,,,,34.2499986290932,,,,,1.02585579715619E-5,1.08032496889633E-8,31.2330798535564,0.00123562775740579,3.41966785735619E-6,3.6012396497396E-9,2.92403841100452E-6,2.28476717372841E-9,1.77316880911131E-6,2.78366053546579E-9,2.99986969479926,303.2802734375,14,4245,1,3,0.0267740388094308,0.0208392059148924,0.00601111585274339,126.320068359375,1.79911732673645,1.80102705955505,2500.26806640625,2500.26806640625,,,2.31700158119202,0,1,,,,,,1,1,1,1.79993033409119,0,0,1.79999604259712,,,,,,,,,,,,,,,,,,,,,,,,,,,,,,,,,
,3590198985.33312,1.80031031370163,2500.26806640625,,,5,,,,34.2499986290932,,,,,5.9653791976306E-6,1.23506998471779E-8,34.3683163201825,0.00592338970695943,1.98840623029309E-6,4.11678917819051E-9,1.64128178371887E-6,2.67260300822975E-9,1.12247647774953E-6,3.13131702292626E-9,3.00008072130779,950.425842285156,14,13305,100,3,0.0127500453909254,0.0150977694599003,0.00779756112024188,89.9746398925781,1.79569590091705,1.80558431148529,2500.26806640625,2500.26806640625,,,2.31596326828003,0,1,,,,,,1,1,1,1.80050182342529,0,0,1.79998791217804,,,,,,,,,,,,,,,,,,,,,,,,,,,,,,,,,
,3590199663.29932,1.79993057250977,3000.13525390625,,,5,,,,34.2499986290932,,,,,1.86343307661041E-5,9.40008816621192E-8,1.35023553798114,0.00299255466282105,6.21143123719623E-6,3.13335649135387E-8,6.20970652993887E-6,2.52366718694925E-8,1.46365386794786E-7,1.85715557545001E-8,3.0000059655358,2.39918065071106,14.1715047551435,33,1,3,0.06172182893282,0.00337514537178689,0.0276229437440634,176.002883911133,1.7988783121109,1.80155897140503,3000.13525390625,3000.13525390625,,,2.31570434570313,0,1,,,,,,1,1,1,1.7999712228775,0,0,1.79999307361809,,,,,,,,,,,,,,,,,,,,,,,,,,,,,,,,,
,3590200051.85131,1.80006617307663,3000.13525390625,,,5,,,,34.2499986290932,,,,,1.74623111316771E-5,9.45666305082042E-8,5.19286601189927,0.00297384442232973,5.82079730067286E-6,3.15223559725348E-8,5.7969068608788E-6,2.65714284357744E-8,5.26832100214834E-7,1.69593076787268E-8,2.9999861238354,7.40717935562134,14,103,1,3,0.0570693449937912,0.00982150130239074,0.0262483265250921,167.193557739258,1.79928588867187,1.80103385448456,3000.13525390625,3000.13525390625,,,2.31542468070984,0,1,,,,,,1,1,1,1.80005931854248,0,0,1.79999826329478,,,,,,,,,,,,,,,,,,,,,,,,,,,,,,,,,
,3590200375.07172,1.80011248588562,3000.13525390625,,,5,,,,34.2499986290932,,,,,1.64538679046197E-5,3.54546571966057E-8,12.24866950594,0.00162181066307022,5.48489748221851E-6,1.18188113043003E-8,5.36003945848956E-6,8.15718600591221E-9,1.16364831194049E-6,8.55246263432976E-9,2.99984967047451,23.2072830200195,14,324,1,3,0.0507514984350395,0.019833603328247,0.0219280011951923,148.555725097656,1.79901421070099,1.80133545398712,3000.13525390625,3000.13525390625,,,2.31638121604919,0,1,,,,,,1,1,1,1.80038523674011,0,0,1.80001363284151,,,,,,,,,,,,,,,,,,,,,,,,,,,,,,,,,
,3590200662.6067,1.79981535673141,3000.13525390625,,,5,,,,34.2499986290932,,,,,1.31353307827853E-5,1.5250964314176E-8,20.8931367970803,0.000978012328826581,4.37834654869009E-6,5.08354209523827E-9,4.09045800222884E-6,3.77477437624674E-9,1.56143262180233E-6,3.40491977034563E-9,3.0000664946714,72.6609039306641,14,1017,1,3,0.0380889707443585,0.0208863895831775,0.0117302192375064,129.960403442383,1.79887115955353,1.80096697807312,3000.13525390625,3000.13525390625,,,2.31631779670715,0,1,,,,,,1,1,1,1.79990243911743,0,0,1.79998751367841,,,,,,,,,,,,,,,,,,,,,,,,,,,,,,,,,
,3590200937.15163,1.79992151260376,3000.13525390625,,,5,,,,34.2499986290932,,,,,9.38789899476113E-6,7.18710580988349E-9,29.366975925362,0.000821767158883547,3.12930867808142E-6,2.39570883684503E-9,2.72718191374157E-6,1.61356167487169E-9,1.53461774135339E-6,1.77083018731967E-9,2.99999135927902,227.636947631836,14,3186,1,3,0.025277643353994,0.0180212452752208,0.00638627540320158,128.419769287109,1.79910027980804,1.80097341537476,3000.13525390625,3000.13525390625,,,2.31640648841858,0,1,,,,,,1,1,1,1.79994964599609,0,0,1.80000089695959,,,,,,,,,,,,,,,,,,,,,,,,,,,,,,,,,
,3590201221.6091,1.79988664388657,3000.13525390625,,,5,,,,34.2499986290932,,,,,6.10860000958939E-6,2.05730304773617E-8,34.1773046554851,0.00809016406277436,2.03611916357899E-6,6.85740456767383E-9,1.68448780875786E-6,5.13227685565809E-9,1.143801587007E-6,4.54793707977917E-9,3.00011910837871,714.122497558594,14,9997,1,3,0.0140076883585832,0.0145896117044711,0.00666411360725761,103.651153564453,1.79653465747833,1.80344259738922,3000.13525390625,3000.13525390625,,,2.31476807594299,0,1,,,,,,1,1,1,1.79996919631958,0,0,1.80001494396164,,,,,,,,,,,,,,,,,,,,,,,,,,,,,,,,,
,3590201862.45806,1.8001714348793,3500.38061523438,,,5,,,,34.2499986290932,,,,,1.57702796478276E-5,5.89329579060024E-8,1.04556319560191,0.00261579530771096,5.2567486017411E-6,1.96442771458095E-8,5.25587335506479E-6,1.40296731163227E-8,9.59225595310624E-8,1.37501235205545E-8,3.00000643793472,1.80150997638702,18.8730567388741,34,1,3,0.0522665678373574,0.00226839897802702,0.0278928130865097,177.065399169922,1.79888868331909,1.80140495300293,3500.38061523438,3500.38061523438,,,2.31454300880432,0,1,,,,,,1,1,1,1.80012381076813,0,0,1.80000013159955,,,,,,,,,,,,,,,,,,,,,,,,,,,,,,,,,
,3590202289.14203,1.80000084638596,3500.38061523438,,,5,,,,34.2499986290932,,,,,1.48292170326083E-5,1.23591100034305E-7,4.08717837608041,0.0034056663861272,4.94307729295607E-6,4.11970745891485E-8,4.93050584930872E-6,3.78459899845143E-8,3.52314056021686E-7,1.62751343096119E-8,2.99999699655517,5.59955549240112,14,78,1,3,0.0487376292265777,0.00661734250356753,0.0272842049598694,169.9794921875,1.79924368858337,1.8010368347168,3500.38061523438,3500.38061523438,,,2.31488752365112,0,1,,,,,,1,1,1,1.79995703697205,0,0,1.80001132919433,,,,,,,,,,,,,,,,,,,,,,,,,,,,,,,,,
,3590202635.90831,1.79975861310959,3500.38061523438,,,5,,,,34.2499986290932,,,,,1.38547069542621E-5,3.67746916806879E-8,10.5431439575742,0.00152537003885205,4.61848112051808E-6,1.22588821113883E-8,4.54050917293659E-6,1.06678952719294E-8,8.45070595311836E-7,6.03955305366722E-9,2.99984055206184,17.3889331817627,14,243,1,3,0.0434745120311476,0.0147351146812656,0.0239111669361591,154.484130859375,1.79924201965332,1.8011771440506,3500.38061523438,3500.38061523438,,,2.31413078308105,0,1,,,,,,1,1,1,1.79965722560883,0,0,1.79999011258284,,,,,,,,,,,,,,,,,,,,,,,,,,,,,,,,,
,3590202925.08045,1.7998993396759,3500.38061523438,,,5,,,,34.2499986290932,,,,,1.16888074770965E-5,1.88542463581096E-8,18.9174038527711,0.0012848612623097,3.89659815539769E-6,6.28527946280048E-9,3.68613090230433E-6,5.21500915608576E-9,1.26329575148725E-6,3.50833542117102E-9,2.99974670493154,54.6175918579102,14,764,1,3,0.0342449356793039,0.0179537481052041,0.0141894426196814,132.880798339844,1.79878413677216,1.8011337518692,3500.38061523438,3500.38061523438,,,2.31480026245117,0,1,,,,,,1,1,1,1.79967749118805,0,0,1.79999851839883,,,,,,,,,,,,,,,,,,,,,,,,,,,,,,,,,
,3590203200.42259,1.79995012283325,3500.38061523438,,,5,,,,34.2499986290932,,,,,8.64137865300325E-6,1.19510702709969E-8,26.8670946694984,0.00139798631631511,2.88045001291743E-6,3.98367689911451E-9,2.56952622698806E-6,3.19108203478892E-9,1.30174008378653E-6,2.38467546718331E-9,3.00000993395158,171.026702880859,14,2394,1,3,0.0239879986445913,0.0155245770395047,0.00714313378557563,128.803573608398,1.79890418052673,1.80126512050629,3500.38061523438,3500.38061523438,,,2.31573677062988,0,1,,,,,,1,1,1,1.79993462562561,0,0,1.80000792099879,,,,,,,,,,,,,,,,,,,,,,,,,,,,,,,,,
,3590203480.90992,1.79987585544586,3500.38061523438,,,5,,,,34.2499986290932,,,,,5.79437923298502E-6,2.01964237353001E-8,32.917627852477,0.00739869669397999,1.93135931572131E-6,6.73179119919848E-9,1.62128481067628E-6,6.16116181112351E-9,1.04956389471717E-6,2.71239707394758E-9,3.00015599677317,536.572814941406,14,7512,1,3,0.0141549664491966,0.0129380670299999,0.00612144498154521,114.299850463867,1.79766547679901,1.80401539802551,3500.38061523438,3500.38061523438,,,2.31487417221069,0,1,,,,,,1,1,1,1.79998755455017,0,0,1.80002497071805,,,,,,,,,,,,,,,,,,,,,,,,,,,,,,,,,
,3590204035.87365,1.80010282993317,4000.19702148438,,,5,,,,34.2499986290932,,,,,1.29889835490197E-5,1.32237718042202E-7,-0.0426200346841119,0.00737614327127946,4.32967434847302E-6,4.40793733818485E-8,4.32967315060891E-6,3.03820254101158E-8,-3.2206709718126E-9,3.19362441391516E-8,2.99999087774365,1.33032166957855,25.5577284633507,33,1,3,0.0430824617229471,0.000850472473139792,0.0277593489736319,177.913116455078,1.79864096641541,1.80182123184204,4000.19702148438,4000.19702148438,,,2.31453394889832,0,1,,,,,,1,1,1,1.80027937889099,0,0,1.79999256860919,,,,,,,,,,,,,,,,,,,,,,,,,,,,,,,,,
,3590204513.90234,1.79975765943527,4000.19702148438,,,5,,,,34.2499986290932,,,,,1.32009240038896E-5,1.11185061693044E-7,2.98906665085099,0.00495051869359699,4.4003072179423E-6,3.70616806331969E-8,4.39432061525831E-6,3.00481030782025E-8,2.29455753013307E-7,2.16951532089266E-8,3.00000053406787,4.2035231590271,14,58,1,3,0.0435595600071779,0.00447980099289907,0.027555713430047,172.946594238281,1.79865419864655,1.80180168151855,4000.19702148438,4000.19702148438,,,2.31333875656128,0,1,,,,,,1,1,1,1.79968476295471,0,0,1.7999813252307,,,,,,,,,,,,,,,,,,,,,,,,,,,,,,,,,
,3590204902.25309,1.8001629114151,4000.19702148438,,,5,,,,34.2499986290932,,,,,1.24301304663477E-5,5.81909184581879E-8,8.87291466953249,0.00222894612156371,4.1432059875515E-6,1.93961730675162E-8,4.09362379128848E-6,1.77591452377897E-8,6.39061898942119E-7,7.79899288935012E-9,3.0001236973722,13.0976734161377,14,183,1,3,0.039629243179934,0.011272145218471,0.0253819208592176,159.80549621582,1.79906296730042,1.8013631105423,4000.19702148438,4000.19702148438,,,2.31424856185913,0,1,,,,,,1,1,1,1.80008292198181,0,0,1.79998262516864,,,,,,,,,,,,,,,,,,,,,,,,,,,,,,,,,
,3590205196.46257,1.80010581016541,4000.19702148438,,,5,,,,34.2499986290932,,,,,1.03441528044998E-5,4.39021663212922E-8,16.6535522540453,0.0030606537158285,3.4479334770175E-6,1.46335569314991E-8,3.30331036769284E-6,1.30801367617468E-8,9.88122399620077E-7,6.5613269055447E-9,3.00010219844717,41.0320358276367,14,574,1,3,0.030748602941321,0.0150397133672599,0.0169604476541281,137.352035522461,1.79881656169891,1.801234126091,4000.19702148438,4000.19702148438,,,2.31476068496704,0,1,,,,,,1,1,1,1.79993951320648,0,0,1.80000293425151,,,,,,,,,,,,,,,,,,,,,,,,,,,,,,,,,
,3590205476.35387,1.80001962184906,4000.19702148438,,,5,,,,34.2499986290932,,,,,7.8900558414188E-6,1.3586480493773E-8,24.476283552051,0.00160326205546843,2.62997171302264E-6,4.52874606927133E-9,2.39362364252655E-6,4.13486701757363E-9,1.08964079826204E-6,1.84727250478165E-9,3.00005349956815,128.495071411133,14,1798,1,3,0.0223977219726452,0.0133789177729814,0.00825969502329826,128.534866333008,1.79943370819092,1.80094337463379,4000.19702148438,4000.19702148438,,,2.31530618667603,0,1,,,,,,1,1,1,1.79993152618408,0,0,1.80000355026939,,,,,,,,,,,,,,,,,,,,,,,,,,,,,,,,,
,3590205756.79996,1.80002522468567,4000.19702148438,,,5,,,,34.2499986290932,,,,,5.54052973180185E-6,2.9156265948581E-8,30.6219072920155,0.00754245335758346,1.84676006564494E-6,9.71831760203406E-9,1.58922444341579E-6,7.9848612977481E-9,9.40685074034184E-7,5.53964683619178E-9,3.00013512035031,403.538238525391,14,5649,1,3,0.0143585364947167,0.0113951294100277,0.00597985694184899,121.76774597168,1.79862642288208,1.80125153064728,4000.19702148438,4000.19702148438,,,2.31491589546204,0,1,,,,,,1,1,1,1.80005133152008,0,0,1.80001640487725,,,,,,,,,,,,,,,,,,,,,,,,,,,,,,,,,
,3590206179.95685,1.80002999305725,4500.49267578125,,,5,,,,34.2499986290932,,,,,4.50354041524008E-7,1.39527249844358E-6,-1.84907642395997,1.36521643894787,1.50117240568399E-7,4.65088437085027E-7,1.5003907286707E-7,4.17487351760536E-7,-4.84381348328917E-9,2.04967230137326E-7,3.00001545338031,1.00057637691498,33.9804144735361,34,1,3,0.00149392960954171,-2.23308138781002E-5,0.0281317736953497,177.959854125977,1.798255443573,1.80128991603851,4500.49267578125,4500.49267578125,,,2.31344294548035,0,1,,,,,,1,1,1,1.79996871948242,0,0,1.79998555121484,,,,,,,,,,,,,,,,,,,,,,,,,,,,,,,,,
,3590206756.99046,1.79997456073761,4500.49267578125,,,5,,,,34.2499986290932,,,,,1.1263309263907E-5,8.89288432626736E-8,2.11460202425294,0.00573327295787712,3.75443906160096E-6,2.96429686005583E-8,3.75188237326886E-6,2.03769659719819E-8,1.38532755800081E-7,2.15286981777899E-8,2.99999789025849,3.13966870307922,14,43,1,3,0.0372550169874006,0.00286498236160486,0.027636431157589,174.940246582031,1.79872834682465,1.80108106136322,4500.49267578125,4500.49267578125,,,2.31353044509888,0,1,,,,,,1,1,1,1.80006670951843,0,0,1.79998364986158,,,,,,,,,,,,,,,,,,,,,,,,,,,,,,,,,
,3590207133.4638,1.80008012056351,4500.49267578125,,,5,,,,34.2499986290932,,,,,1.064823535042E-5,6.99483707571695E-8,7.13389251440001,0.00352028570756552,3.54931732189412E-6,2.33155030666091E-8,3.52184081266392E-6,2.00674528327279E-8,4.40784234918162E-7,1.18705526432134E-8,3.00007984204058,9.82852745056152,14,137,1,3,0.0344158113160797,0.00788241119981121,0.0266201607882977,164.300399780273,1.79886341094971,1.80147671699524,4500.49267578125,4500.49267578125,,,2.31388926506042,0,1,,,,,,1,1,1,1.79989326000214,0,0,1.8000163924828,,,,,,,,,,,,,,,,,,,,,,,,,,,,,,,,,
,3590207437.01319,1.79998534917831,4500.49267578125,,,5,,,,34.2499986290932,,,,,9.1339573273319E-6,4.57462281609098E-8,14.5313069210833,0.00395277432057326,3.04472961333088E-6,1.52491292205762E-8,2.94733080170958E-6,1.00674204782485E-8,7.63949974532325E-7,1.14535141725138E-8,2.99992396281768,30.8258380889893,14,431,1,3,0.0275983838175804,0.012355231352379,0.0196814425289631,142.891326904297,1.79915714263916,1.80154263973236,4500.49267578125,4500.49267578125,,,2.31449580192566,0,1,,,,,,1,1,1,1.80007374286652,0,0,1.79996699850324,,,,,,,,,,,,,,,,,,,,,,,,,,,,,,,,,
,3590207722.11226,1.80009782314301,4500.49267578125,,,5,,,,34.2499986290932,,,,,7.29446616133134E-6,1.75101559557286E-8,22.3701752043396,0.00205833781333658,2.43146835997917E-6,5.83666977720058E-9,2.24848643614164E-6,5.01709048823947E-9,9.25390259332172E-7,2.98253535115742E-9,3.00002512119624,96.6893615722656,14,1353,1,3,0.0210132133697752,0.0118457401944484,0.00981724262237549,128.751541137695,1.79841494560242,1.80090224742889,4500.49267578125,4500.49267578125,,,2.31556463241577,0,1,,,,,,1,1,1,1.80006957054138,0,0,1.80000987223216,,,,,,,,,,,,,,,,,,,,,,,,,,,,,,,,,
,3590207995.25357,1.80000221729279,4500.49267578125,,,5,,,,34.2499986290932,,,,,5.27776812563104E-6,1.92764859303468E-8,27.859564905749,0.00338187918966728,1.75928174360149E-6,6.42558918292669E-9,1.55537331904521E-6,3.00571634317206E-9,8.2212291767825E-7,5.67924868377261E-9,2.9999561723563,303.2802734375,14,4245,1,3,0.0143692750009482,0.00991354831300417,0.00613609701395035,126.287109375,1.79898881912231,1.80121457576752,4500.49267578125,4500.49267578125,,,2.31558704376221,0,1,,,,,,1,1,1,1.80013251304626,0,0,1.80001355069024,,,,,,,,,,,,,,,,,,,,,,,,,,,,,,,,,
,3590208310.55664,1.79999577999115,4500.49267578125,,,5,,,,34.2499986290932,,,,,4.58342380282534E-6,2.98693251137817E-8,48.9691406921309,0.0984989096102071,1.52774293505092E-6,9.9560181166729E-9,1.0029104041079E-6,5.93341186827775E-9,1.15246223232265E-6,7.99480583509692E-9,3.00012763775117,950.425842285156,14,13305,100,3,0.00653785109775634,0.0137055639933995,0.00790288578718901,89.8358764648438,1.79591929912567,1.80495488643646,4500.49267578125,4500.49267578125,,,2.31311964988709,0,1,,,,,,1,1,1,1.79993748664856,0,0,1.80002864363582,,,,,,,,,,,,,,,,,,,,,,,,,,,,,,,,,
,3590209005.24705,1.800053358078,5000.1708984375,,,5,,,,34.2499986290932,,,,,9.45412536939665E-6,8.94432460989486E-8,0.889403588350382,0.00790125418149212,3.15137410602859E-6,2.98144057437392E-8,3.15099442951274E-6,1.63848627558222E-8,4.89168818221076E-8,2.49085339256484E-8,3.00000096824775,2.39918065071106,14.1715047551435,33,1,3,0.031328834087757,0.00150558080183865,0.0276688281446695,175.683380126953,1.79921746253967,1.80118954181671,5000.1708984375,5000.1708984375,,,2.31365656852722,0,1,,,,,,1,1,1,1.80009627342224,0,0,1.79999519519086,,,,,,,,,,,,,,,,,,,,,,,,,,,,,,,,,
,3590209397.60207,1.80012446641922,5000.1708984375,,,5,,,,34.2499986290932,,,,,9.10404968104299E-6,9.44777943676315E-8,5.55130510599536,0.00741003427367912,3.03471032754078E-6,3.14928793598014E-8,3.02047745994834E-6,2.20861578155567E-8,2.93568877823772E-7,2.24500129914735E-8,2.99997320944321,7.40717935562134,14,103,1,3,0.0297165394354411,0.00534975936016076,0.0268572978675365,169.613922119141,1.79905986785889,1.8010425567627,5000.1708984375,5000.1708984375,,,2.31360769271851,0,1,,,,,,1,1,1,1.80000281333923,0,0,1.79999471246526,,,,,,,,,,,,,,,,,,,,,,,,,,,,,,,,,
,3590209720.36518,1.80005568265915,5000.1708984375,,,5,,,,34.2499986290932,,,,,8.27256849852107E-6,4.66316428540374E-8,12.2396710103259,0.00438975974487089,2.75761066397604E-6,1.55443760466903E-8,2.69492835600668E-6,1.00411134196857E-8,5.84617593017428E-7,1.18660721375662E-8,2.99990444865532,23.2072830200195,14,324,1,3,0.0255067258906073,0.0100055241898625,0.0221414510160685,148.81071472168,1.79910373687744,1.80123865604401,5000.1708984375,5000.1708984375,,,2.31459522247314,0,1,,,,,,1,1,1,1.80000674724579,0,0,1.80000699405939,,,,,,,,,,,,,,,,,,,,,,,,,,,,,,,,,
,3590210008.1774,1.80023688077927,5000.1708984375,,,5,,,,34.2499986290932,,,,,6.64603770155641E-6,4.21394356980838E-8,20.1219047030072,0.00508380114755811,2.21549052716513E-6,1.40473955763635E-8,2.08026318700926E-6,1.21953318844547E-8,7.62170157335274E-7,6.97159972365301E-9,2.999804160779,72.6609039306641,14,1017,1,3,0.0193997439888688,0.0103363929894415,0.0119125377386808,130.161010742188,1.7992490530014,1.80121874809265,5000.1708984375,5000.1708984375,,,2.31441521644592,0,1,,,,,,1,1,1,1.80000996589661,0,0,1.80000318288803,,,,,,,,,,,,,,,,,,,,,,,,,,,,,,,,,
,3590210287.13281,1.79960805177689,5000.1708984375,,,5,,,,34.2499986290932,,,,,5.00477109957746E-6,1.03519729776841E-8,25.7818336639826,0.00198798047397854,1.66827537906256E-6,3.45069560620852E-9,1.50220977847779E-6,2.71863967446486E-9,7.25609069562973E-7,2.12515846165231E-9,2.99996700927742,227.636947631836,14,3186,1,3,0.0140393401925304,0.00876674701773174,0.00651972461491823,128.41731262207,1.79929029941559,1.80086064338684,5000.1708984375,5000.1708984375,,,2.3147075176239,0,1,,,,,,1,1,1,1.7996096611023,0,0,1.8000037414687,,,,,,,,,,,,,,,,,,,,,,,,,,,,,,,,,
,3590210571.12901,1.79997485876083,5000.1708984375,,,5,,,,34.2499986290932,,,,,3.66942952998926E-6,6.39074089735355E-8,31.1158342106993,0.0340747102764106,1.22309186384786E-6,2.13015759851254E-8,1.0471186697011E-6,1.66127457611786E-8,6.32057116860669E-7,1.33331848305088E-8,3.00012586008478,714.122497558594,14,9991,1,3,0.00886001528181545,0.00831526842268117,0.00675847940146923,103.457672119141,1.79638969898224,1.80415606498718,5000.1708984375,5000.1708984375,,,2.31400513648987,0,1,,,,,,1,1,1,1.7999769449234,0,0,1.80004429306303,,,,,,,,,,,,,,,,,,,,,,,,,,,,,,,,,
,3590210685.633,1.79999804496765,5000.1708984375,,,5,,,,34.2499986290932,,,,,2.90620993633901E-6,1.37138921459328E-8,35.8565106714896,0.0171607043206301,9.6874362287714E-7,4.57133030724302E-9,7.85153611277214E-7,3.20190468640441E-9,5.67448688044545E-7,3.26264726213239E-9,2.99997839233011,950.425842285156,14,13305,100,3,0.00600650737788155,0.00752549239492357,0.00791375339031219,89.7671203613281,1.79473102092743,1.80659401416779,5000.1708984375,5000.1708984375,,,2.31311202049255,0,1,,,,,,1,1,1,1.80006694793701,0,0,1.80000163523804,,,,,,,,,,,,,,,,,,,,,,,,,,,,,,,,,